Workbook

Sheet Runs
A1: Run | B1: Mode | C1: Bot | D1: Seed(s) | E1: Tenders | F1: Accepts | G1: Gaps | H1: Journal P&L | I1: Current bot on this market
A2: 20261011-094605 | B2: local | C2: v3-late-guard | D2: 7 | E2: 35 | F2: 21 | G2: 4 | H2: 46854.16 | I2: 49167.146

Sheet Tenders
A1: Row | B1: Tender ID | C1: Type | D1: Side (ours) | E1: Security | F1: Volume (+buy) | G1: Price | H1: Tick received | I1: Tick expired | J1: Answer tick | K1: Bot answer | L1: Bot est./share | M1: Bot bid | N1: Mid at answer | O1: Mid at arrival | P1: Edge vs mid at arrival | Q1: Hidden reserve | R1: Rival bid | S1: Bid vs reserve | T1: Outcome | U1: Gap flag | V1: Book tick | W1: Edge declined ($) | X1: Seed | Y1: Realized/share | Z1: Source
A2: 1 | B2: 1 | C2: private | D2: BUY | E2: CROC | F2: 30000 | G2: 20.15 | H2: 21 | I2: 48 | J2: 44 | K2: decline | L2: -0.0527 | N2: 20.185 | O2: 20.251524 | P2: =IF(OR(G2="",O2=""),"",SIGN(F2)*(O2-G2)) | Q2: 20.22 | S2: =IF(OR(M2="",Q2=""),"",SIGN(F2)*(M2-Q2)) | U2: =IF(K2="not answered","not answered",IF(AND(K2="decline",C2="private",N(P2)>0.1),"declined: 10c+ inside the mid",IF(AND(S2<>"",N(S2)<0),"bid short of the reserve",""))) | V2: 44 | W2: =IF(U2="declined: 10c+ inside the mid",P2*ABS(F2),0) | X2: 7 | Z2: run 20261011-094605 (local)
A3: 2 | B3: 2 | C3: private | D3: BUY | E3: CRZY | F3: 20000 | G3: 10.01 | H3: 46 | I3: 68 | J3: 66 | K3: ACCEPT | L3: 0.0588 | N3: 10.135 | O3: 10.098931 | P3: =IF(OR(G3="",O3=""),"",SIGN(F3)*(O3-G3)) | Q3: 10.02 | S3: =IF(OR(M3="",Q3=""),"",SIGN(F3)*(M3-Q3)) | U3: =IF(K3="not answered","not answered",IF(AND(K3="decline",C3="private",N(P3)>0.1),"declined: 10c+ inside the mid",IF(AND(S3<>"",N(S3)<0),"bid short of the reserve",""))) | V3: 66 | W3: =IF(U3="declined: 10c+ inside the mid",P3*ABS(F3),0) | X3: 7 | Z3: run 20261011-094605 (local)
A4: 3 | B4: 26 | C4: private | D4: BUY | E4: TAME | F4: 30000 | G4: 25.51 | H4: 125 | I4: 145 | J4: 142 | K4: ACCEPT | L4: 0.1125 | N4: 25.735 | O4: 25.658185 | P4: =IF(OR(G4="",O4=""),"",SIGN(F4)*(O4-G4)) | Q4: 25.59 | S4: =IF(OR(M4="",Q4=""),"",SIGN(F4)*(M4-Q4)) | U4: =IF(K4="not answered","not answered",IF(AND(K4="decline",C4="private",N(P4)>0.1),"declined: 10c+ inside the mid",IF(AND(S4<>"",N(S4)<0),"bid short of the reserve",""))) | V4: 142 | W4: =IF(U4="declined: 10c+ inside the mid",P4*ABS(F4),0) | X4: 7 | Z4: run 20261011-094605 (local)
A5: 4 | B5: 27 | C5: private | D5: SELL | E5: CRZY | F5: -50000 | G5: 10.44 | H5: 127 | I5: 146 | J5: 144 | K5: decline | L5: -0.0411 | N5: 10.325 | O5: 10.378278 | P5: =IF(OR(G5="",O5=""),"",SIGN(F5)*(O5-G5)) | Q5: 10.52 | S5: =IF(OR(M5="",Q5=""),"",SIGN(F5)*(M5-Q5)) | U5: =IF(K5="not answered","not answered",IF(AND(K5="decline",C5="private",N(P5)>0.1),"declined: 10c+ inside the mid",IF(AND(S5<>"",N(S5)<0),"bid short of the reserve",""))) | V5: 144 | W5: =IF(U5="declined: 10c+ inside the mid",P5*ABS(F5),0) | X5: 7 | Z5: run 20261011-094605 (local)
A6: 5 | B6: 28 | C6: private | D6: SELL | E6: CRZY | F6: -20000 | G6: 10.27 | H6: 134 | I6: 155 | J6: 152 | K6: decline | L6: -0.013 | N6: 10.235 | O6: 10.332523 | P6: =IF(OR(G6="",O6=""),"",SIGN(F6)*(O6-G6)) | Q6: 10.43 | S6: =IF(OR(M6="",Q6=""),"",SIGN(F6)*(M6-Q6)) | U6: =IF(K6="not answered","not answered",IF(AND(K6="decline",C6="private",N(P6)>0.1),"declined: 10c+ inside the mid",IF(AND(S6<>"",N(S6)<0),"bid short of the reserve",""))) | V6: 152 | W6: =IF(U6="declined: 10c+ inside the mid",P6*ABS(F6),0) | X6: 7 | Z6: run 20261011-094605 (local)
A7: 6 | B7: 29 | C7: private | D7: BUY | E7: CRZY | F7: 50000 | G7: 10.24 | H7: 136 | I7: 159 | J7: 156 | K7: decline | L7: -0.4211 | N7: 10.175 | O7: 10.322736 | P7: =IF(OR(G7="",O7=""),"",SIGN(F7)*(O7-G7)) | Q7: 10.19 | S7: =IF(OR(M7="",Q7=""),"",SIGN(F7)*(M7-Q7)) | U7: =IF(K7="not answered","not answered",IF(AND(K7="decline",C7="private",N(P7)>0.1),"declined: 10c+ inside the mid",IF(AND(S7<>"",N(S7)<0),"bid short of the reserve",""))) | V7: 156 | W7: =IF(U7="declined: 10c+ inside the mid",P7*ABS(F7),0) | X7: 7 | Z7: run 20261011-094605 (local)
A8: 7 | B8: 37 | C8: private | D8: SELL | E8: CROC | F8: -10000 | G8: 20.12 | H8: 152 | I8: 176 | J8: 173 | K8: ACCEPT | L8: 0.2213 | N8: 19.825 | O8: 19.877298 | P8: =IF(OR(G8="",O8=""),"",SIGN(F8)*(O8-G8)) | Q8: 19.89 | S8: =IF(OR(M8="",Q8=""),"",SIGN(F8)*(M8-Q8)) | U8: =IF(K8="not answered","not answered",IF(AND(K8="decline",C8="private",N(P8)>0.1),"declined: 10c+ inside the mid",IF(AND(S8<>"",N(S8)<0),"bid short of the reserve",""))) | V8: 173 | W8: =IF(U8="declined: 10c+ inside the mid",P8*ABS(F8),0) | X8: 7 | Z8: run 20261011-094605 (local)
A9: 8 | B9: 45 | C9: auction | D9: SELL | E9: CRZY | F9: -50000 | H9: 158 | I9: 188 | J9: 158 | K9: ACCEPT | L9: 0.05 | M9: 10.36 | N9: 10.155 | O9: 10.150118 | P9: =IF(OR(G9="",O9=""),"",SIGN(F9)*(O9-G9)) | Q9: 10.29 | S9: =IF(OR(M9="",Q9=""),"",SIGN(F9)*(M9-Q9)) | T9: rejected | U9: =IF(K9="not answered","not answered",IF(AND(K9="decline",C9="private",N(P9)>0.1),"declined: 10c+ inside the mid",IF(AND(S9<>"",N(S9)<0),"bid short of the reserve",""))) | V9: 158 | W9: =IF(U9="declined: 10c+ inside the mid",P9*ABS(F9),0) | X9: 7 | Z9: run 20261011-094605 (local)
A10: 9 | B10: 47 | C10: private | D10: SELL | E10: TAME | F10: -20000 | G10: 25.7 | H10: 159 | I10: 175 | J10: 172 | K10: ACCEPT | L10: 0.0377 | N10: 25.595 | O10: 25.750814 | P10: =IF(OR(G10="",O10=""),"",SIGN(F10)*(O10-G10)) | Q10: 25.75 | S10: =IF(OR(M10="",Q10=""),"",SIGN(F10)*(M10-Q10)) | U10: =IF(K10="not answered","not answered",IF(AND(K10="decline",C10="private",N(P10)>0.1),"declined: 10c+ inside the mid",IF(AND(S10<>"",N(S10)<0),"bid short of the reserve",""))) | V10: 172 | W10: =IF(U10="declined: 10c+ inside the mid",P10*ABS(F10),0) | X10: 7 | Z10: run 20261011-094605 (local)
A11: 10 | B11: 48 | C11: private | D11: SELL | E11: CRZY | F11: -30000 | G11: 10.43 | H11: 165 | I11: 194 | J11: 191 | K11: decline | L11: -0.02 | N11: 10.345 | O11: 10.256682 | P11: =IF(OR(G11="",O11=""),"",SIGN(F11)*(O11-G11)) | Q11: 10.26 | S11: =IF(OR(M11="",Q11=""),"",SIGN(F11)*(M11-Q11)) | U11: =IF(K11="not answered","not answered",IF(AND(K11="decline",C11="private",N(P11)>0.1),"declined: 10c+ inside the mid",IF(AND(S11<>"",N(S11)<0),"bid short of the reserve",""))) | V11: 191 | W11: =IF(U11="declined: 10c+ inside the mid",P11*ABS(F11),0) | X11: 7 | Z11: run 20261011-094605 (local)
A12: 11 | B12: 49 | C12: private | D12: SELL | E12: CROC | F12: -20000 | G12: 20.05 | H12: 167 | I12: 197 | J12: 194 | K12: decline | L12: -0.2273 | N12: 20.125 | O12: 19.892827 | P12: =IF(OR(G12="",O12=""),"",SIGN(F12)*(O12-G12)) | Q12: 19.93 | S12: =IF(OR(M12="",Q12=""),"",SIGN(F12)*(M12-Q12)) | U12: =IF(K12="not answered","not answered",IF(AND(K12="decline",C12="private",N(P12)>0.1),"declined: 10c+ inside the mid",IF(AND(S12<>"",N(S12)<0),"bid short of the reserve",""))) | V12: 194 | W12: =IF(U12="declined: 10c+ inside the mid",P12*ABS(F12),0) | X12: 7 | Z12: run 20261011-094605 (local)
A13: 12 | B13: 62 | C13: auction | D13: BUY | E13: CRZY | F13: 50000 | H13: 188 | I13: 211 | J13: 208 | K13: decline | N13: 10.285 | O13: 10.318961 | P13: =IF(OR(G13="",O13=""),"",SIGN(F13)*(O13-G13)) | Q13: 10.25 | S13: =IF(OR(M13="",Q13=""),"",SIGN(F13)*(M13-Q13)) | U13: =IF(K13="not answered","not answered",IF(AND(K13="decline",C13="private",N(P13)>0.1),"declined: 10c+ inside the mid",IF(AND(S13<>"",N(S13)<0),"bid short of the reserve",""))) | V13: 208 | W13: =IF(U13="declined: 10c+ inside the mid",P13*ABS(F13),0) | X13: 7 | Z13: run 20261011-094605 (local)
A14: 13 | B14: 63 | C14: private | D14: BUY | E14: TAME | F14: 30000 | G14: 25.44 | H14: 189 | I14: 204 | J14: 202 | K14: ACCEPT | L14: 0.0507 | N14: 25.575 | O14: 25.564307 | P14: =IF(OR(G14="",O14=""),"",SIGN(F14)*(O14-G14)) | Q14: 25.49 | S14: =IF(OR(M14="",Q14=""),"",SIGN(F14)*(M14-Q14)) | U14: =IF(K14="not answered","not answered",IF(AND(K14="decline",C14="private",N(P14)>0.1),"declined: 10c+ inside the mid",IF(AND(S14<>"",N(S14)<0),"bid short of the reserve",""))) | V14: 202 | W14: =IF(U14="declined: 10c+ inside the mid",P14*ABS(F14),0) | X14: 7 | Z14: run 20261011-094605 (local)
A15: 14 | B15: 64 | C15: wta | D15: BUY | E15: CROC | F15: 30000 | H15: 192 | I15: 208 | J15: 205 | K15: ACCEPT | L15: 0.05 | M15: 20.1 | N15: 20.225 | O15: 20.037685 | P15: =IF(OR(G15="",O15=""),"",SIGN(F15)*(O15-G15)) | Q15: 19.97 | R15: 20.03 | S15: =IF(OR(M15="",Q15=""),"",SIGN(F15)*(M15-Q15)) | U15: =IF(K15="not answered","not answered",IF(AND(K15="decline",C15="private",N(P15)>0.1),"declined: 10c+ inside the mid",IF(AND(S15<>"",N(S15)<0),"bid short of the reserve",""))) | V15: 205 | W15: =IF(U15="declined: 10c+ inside the mid",P15*ABS(F15),0) | X15: 7 | Z15: run 20261011-094605 (local)
A16: 15 | B16: 65 | C16: private | D16: SELL | E16: CROC | F16: -30000 | G16: 20.18 | H16: 193 | I16: 220 | J16: 217 | K16: decline | L16: -0.0264 | N16: 20.135 | O16: 20.056658 | P16: =IF(OR(G16="",O16=""),"",SIGN(F16)*(O16-G16)) | Q16: 20.14 | S16: =IF(OR(M16="",Q16=""),"",SIGN(F16)*(M16-Q16)) | U16: =IF(K16="not answered","not answered",IF(AND(K16="decline",C16="private",N(P16)>0.1),"declined: 10c+ inside the mid",IF(AND(S16<>"",N(S16)<0),"bid short of the reserve",""))) | V16: 217 | W16: =IF(U16="declined: 10c+ inside the mid",P16*ABS(F16),0) | X16: 7 | Z16: run 20261011-094605 (local)
A17: 16 | B17: 66 | C17: private | D17: SELL | E17: TAME | F17: -50000 | G17: 25.71 | H17: 198 | I17: 225 | J17: 223 | K17: ACCEPT | L17: 0.0759 | N17: 25.555 | O17: 25.571588 | P17: =IF(OR(G17="",O17=""),"",SIGN(F17)*(O17-G17)) | Q17: 25.61 | S17: =IF(OR(M17="",Q17=""),"",SIGN(F17)*(M17-Q17)) | U17: =IF(K17="not answered","not answered",IF(AND(K17="decline",C17="private",N(P17)>0.1),"declined: 10c+ inside the mid",IF(AND(S17<>"",N(S17)<0),"bid short of the reserve",""))) | V17: 223 | W17: =IF(U17="declined: 10c+ inside the mid",P17*ABS(F17),0) | X17: 7 | Z17: run 20261011-094605 (local)
A18: 17 | B18: 67 | C18: private | D18: BUY | E18: CRZY | F18: 30000 | G18: 10.23 | H18: 214 | I18: 232 | J18: 228 | K18: decline | L18: -0.1495 | N18: 10.235 | O18: 10.240478 | P18: =IF(OR(G18="",O18=""),"",SIGN(F18)*(O18-G18)) | Q18: 10.11 | S18: =IF(OR(M18="",Q18=""),"",SIGN(F18)*(M18-Q18)) | U18: =IF(K18="not answered","not answered",IF(AND(K18="decline",C18="private",N(P18)>0.1),"declined: 10c+ inside the mid",IF(AND(S18<>"",N(S18)<0),"bid short of the reserve",""))) | V18: 228 | W18: =IF(U18="declined: 10c+ inside the mid",P18*ABS(F18),0) | X18: 7 | Z18: run 20261011-094605 (local)
A19: 18 | B19: 75 | C19: private | D19: SELL | E19: TAME | F19: -50000 | G19: 25.55 | H19: 225 | I19: 255 | J19: 224 | K19: decline | N19: 25.525 | O19: 25.527425 | P19: =IF(OR(G19="",O19=""),"",SIGN(F19)*(O19-G19)) | Q19: 25.53 | S19: =IF(OR(M19="",Q19=""),"",SIGN(F19)*(M19-Q19)) | U19: =IF(K19="not answered","not answered",IF(AND(K19="decline",C19="private",N(P19)>0.1),"declined: 10c+ inside the mid",IF(AND(S19<>"",N(S19)<0),"bid short of the reserve",""))) | V19: 224 | W19: =IF(U19="declined: 10c+ inside the mid",P19*ABS(F19),0) | X19: 7 | Z19: run 20261011-094605 (local)
A20: 19 | B20: 81 | C20: private | D20: SELL | E20: CROC | F20: -30000 | G20: 20.07 | H20: 229 | I20: 249 | J20: 247 | K20: ACCEPT | L20: 0.0951 | N20: 19.895 | O20: 19.958358 | P20: =IF(OR(G20="",O20=""),"",SIGN(F20)*(O20-G20)) | Q20: 20.02 | S20: =IF(OR(M20="",Q20=""),"",SIGN(F20)*(M20-Q20)) | U20: =IF(K20="not answered","not answered",IF(AND(K20="decline",C20="private",N(P20)>0.1),"declined: 10c+ inside the mid",IF(AND(S20<>"",N(S20)<0),"bid short of the reserve",""))) | V20: 247 | W20: =IF(U20="declined: 10c+ inside the mid",P20*ABS(F20),0) | X20: 7 | Z20: run 20261011-094605 (local)
A21: 20 | B21: 85 | C21: private | D21: BUY | E21: TAME | F21: 30000 | G21: 25.49 | H21: 231 | I21: 258 | J21: 256 | K21: ACCEPT | L21: 0.0125 | N21: 25.595 | O21: 25.570648 | P21: =IF(OR(G21="",O21=""),"",SIGN(F21)*(O21-G21)) | Q21: 25.43 | S21: =IF(OR(M21="",Q21=""),"",SIGN(F21)*(M21-Q21)) | U21: =IF(K21="not answered","not answered",IF(AND(K21="decline",C21="private",N(P21)>0.1),"declined: 10c+ inside the mid",IF(AND(S21<>"",N(S21)<0),"bid short of the reserve",""))) | V21: 256 | W21: =IF(U21="declined: 10c+ inside the mid",P21*ABS(F21),0) | X21: 7 | Z21: run 20261011-094605 (local)
A22: 21 | B22: 88 | C22: auction | D22: SELL | E22: CRZY | F22: -50000 | H22: 252 | I22: 278 | J22: 275 | K22: ACCEPT | L22: 0.05 | M22: 10.74 | N22: 10.405 | O22: 10.26378 | P22: =IF(OR(G22="",O22=""),"",SIGN(F22)*(O22-G22)) | Q22: 10.36 | S22: =IF(OR(M22="",Q22=""),"",SIGN(F22)*(M22-Q22)) | T22: rejected | U22: =IF(K22="not answered","not answered",IF(AND(K22="decline",C22="private",N(P22)>0.1),"declined: 10c+ inside the mid",IF(AND(S22<>"",N(S22)<0),"bid short of the reserve",""))) | V22: 275 | W22: =IF(U22="declined: 10c+ inside the mid",P22*ABS(F22),0) | X22: 7 | Z22: run 20261011-094605 (local)
A23: 22 | B23: 92 | C23: private | D23: BUY | E23: CRZY | F23: 50000 | G23: 10.33 | H23: 255 | I23: 283 | J23: 279 | K23: decline | L23: -0.1248 | N23: 10.425 | O23: 10.322267 | P23: =IF(OR(G23="",O23=""),"",SIGN(F23)*(O23-G23)) | Q23: 10.17 | S23: =IF(OR(M23="",Q23=""),"",SIGN(F23)*(M23-Q23)) | U23: =IF(K23="not answered","not answered",IF(AND(K23="decline",C23="private",N(P23)>0.1),"declined: 10c+ inside the mid",IF(AND(S23<>"",N(S23)<0),"bid short of the reserve",""))) | V23: 279 | W23: =IF(U23="declined: 10c+ inside the mid",P23*ABS(F23),0) | X23: 7 | Z23: run 20261011-094605 (local)
A24: 23 | B24: 114 | C24: private | D24: BUY | E24: CROC | F24: 10000 | G24: 19.86 | H24: 272 | I24: 292 | J24: 288 | K24: ACCEPT | L24: 0.1714 | N24: 20.105 | O24: 20.075901 | P24: =IF(OR(G24="",O24=""),"",SIGN(F24)*(O24-G24)) | Q24: 19.95 | S24: =IF(OR(M24="",Q24=""),"",SIGN(F24)*(M24-Q24)) | U24: =IF(K24="not answered","not answered",IF(AND(K24="decline",C24="private",N(P24)>0.1),"declined: 10c+ inside the mid",IF(AND(S24<>"",N(S24)<0),"bid short of the reserve",""))) | V24: 288 | W24: =IF(U24="declined: 10c+ inside the mid",P24*ABS(F24),0) | X24: 7 | Z24: run 20261011-094605 (local)
A25: 24 | B25: 115 | C25: wta | D25: SELL | E25: CRZY | F25: -10000 | H25: 275 | I25: 296 | J25: 293 | K25: ACCEPT | L25: 0.05 | M25: 10.54 | N25: 10.445 | O25: 10.408588 | P25: =IF(OR(G25="",O25=""),"",SIGN(F25)*(O25-G25)) | Q25: 10.45 | R25: 10.4 | S25: =IF(OR(M25="",Q25=""),"",SIGN(F25)*(M25-Q25)) | U25: =IF(K25="not answered","not answered",IF(AND(K25="decline",C25="private",N(P25)>0.1),"declined: 10c+ inside the mid",IF(AND(S25<>"",N(S25)<0),"bid short of the reserve",""))) | V25: 293 | W25: =IF(U25="declined: 10c+ inside the mid",P25*ABS(F25),0) | X25: 7 | Z25: run 20261011-094605 (local)
A26: 25 | B26: 116 | C26: private | D26: BUY | E26: CRZY | F26: 50000 | G26: 10.45 | H26: 286 | I26: 313 | J26: 310 | K26: decline | L26: -0.2756 | N26: 10.395 | O26: 10.521272 | P26: =IF(OR(G26="",O26=""),"",SIGN(F26)*(O26-G26)) | Q26: 10.48 | S26: =IF(OR(M26="",Q26=""),"",SIGN(F26)*(M26-Q26)) | U26: =IF(K26="not answered","not answered",IF(AND(K26="decline",C26="private",N(P26)>0.1),"declined: 10c+ inside the mid",IF(AND(S26<>"",N(S26)<0),"bid short of the reserve",""))) | V26: 310 | W26: =IF(U26="declined: 10c+ inside the mid",P26*ABS(F26),0) | X26: 7 | Z26: run 20261011-094605 (local)
A27: 26 | B27: 119 | C27: auction | D27: BUY | E27: TAME | F27: 30000 | H27: 294 | I27: 324 | J27: 320 | K27: ACCEPT | L27: 0.05 | M27: 25.45 | N27: 25.565 | O27: 25.544859 | P27: =IF(OR(G27="",O27=""),"",SIGN(F27)*(O27-G27)) | Q27: 25.52 | S27: =IF(OR(M27="",Q27=""),"",SIGN(F27)*(M27-Q27)) | T27: rejected | U27: =IF(K27="not answered","not answered",IF(AND(K27="decline",C27="private",N(P27)>0.1),"declined: 10c+ inside the mid",IF(AND(S27<>"",N(S27)<0),"bid short of the reserve",""))) | V27: 320 | W27: =IF(U27="declined: 10c+ inside the mid",P27*ABS(F27),0) | X27: 7 | Z27: run 20261011-094605 (local)
A28: 27 | B28: 122 | C28: auction | D28: BUY | E28: TAME | F28: 50000 | H28: 304 | I28: 326 | J28: 322 | K28: ACCEPT | L28: 0.05 | M28: 25.49 | N28: 25.595 | O28: 25.640806 | P28: =IF(OR(G28="",O28=""),"",SIGN(F28)*(O28-G28)) | Q28: 25.61 | S28: =IF(OR(M28="",Q28=""),"",SIGN(F28)*(M28-Q28)) | T28: rejected | U28: =IF(K28="not answered","not answered",IF(AND(K28="decline",C28="private",N(P28)>0.1),"declined: 10c+ inside the mid",IF(AND(S28<>"",N(S28)<0),"bid short of the reserve",""))) | V28: 322 | W28: =IF(U28="declined: 10c+ inside the mid",P28*ABS(F28),0) | X28: 7 | Z28: run 20261011-094605 (local)
A29: 28 | B29: 123 | C29: auction | D29: SELL | E29: CROC | F29: -30000 | H29: 328 | I29: 350 | J29: 347 | K29: ACCEPT | L29: 0.05 | M29: 20.89 | N29: 20.715 | O29: 20.529358 | P29: =IF(OR(G29="",O29=""),"",SIGN(F29)*(O29-G29)) | Q29: 20.66 | S29: =IF(OR(M29="",Q29=""),"",SIGN(F29)*(M29-Q29)) | T29: rejected | U29: =IF(K29="not answered","not answered",IF(AND(K29="decline",C29="private",N(P29)>0.1),"declined: 10c+ inside the mid",IF(AND(S29<>"",N(S29)<0),"bid short of the reserve",""))) | V29: 347 | W29: =IF(U29="declined: 10c+ inside the mid",P29*ABS(F29),0) | X29: 7 | Z29: run 20261011-094605 (local)
A30: 29 | B30: 124 | C30: private | D30: SELL | E30: CROC | F30: -20000 | G30: 20.82 | H30: 341 | I30: 370 | J30: 367 | K30: ACCEPT | L30: 0.2423 | N30: 20.445 | O30: 20.569687 | P30: =IF(OR(G30="",O30=""),"",SIGN(F30)*(O30-G30)) | Q30: 20.66 | S30: =IF(OR(M30="",Q30=""),"",SIGN(F30)*(M30-Q30)) | U30: =IF(K30="not answered","not answered",IF(AND(K30="decline",C30="private",N(P30)>0.1),"declined: 10c+ inside the mid",IF(AND(S30<>"",N(S30)<0),"bid short of the reserve",""))) | V30: 367 | W30: =IF(U30="declined: 10c+ inside the mid",P30*ABS(F30),0) | X30: 7 | Z30: run 20261011-094605 (local)
A31: 30 | B31: 125 | C31: private | D31: SELL | E31: CROC | F31: -50000 | G31: 20.57 | H31: 344 | I31: 362 | J31: 359 | K31: decline | L31: -0.1568 | N31: 20.625 | O31: 20.644567 | P31: =IF(OR(G31="",O31=""),"",SIGN(F31)*(O31-G31)) | Q31: 20.69 | S31: =IF(OR(M31="",Q31=""),"",SIGN(F31)*(M31-Q31)) | U31: =IF(K31="not answered","not answered",IF(AND(K31="decline",C31="private",N(P31)>0.1),"declined: 10c+ inside the mid",IF(AND(S31<>"",N(S31)<0),"bid short of the reserve",""))) | V31: 359 | W31: =IF(U31="declined: 10c+ inside the mid",P31*ABS(F31),0) | X31: 7 | Z31: run 20261011-094605 (local)
A32: 31 | B32: 126 | C32: auction | D32: BUY | E32: CROC | F32: 10000 | H32: 355 | I32: 385 | J32: 382 | K32: ACCEPT | L32: 0.05 | M32: 20.53 | N32: 20.595 | O32: 20.69846 | P32: =IF(OR(G32="",O32=""),"",SIGN(F32)*(O32-G32)) | Q32: 20.63 | S32: =IF(OR(M32="",Q32=""),"",SIGN(F32)*(M32-Q32)) | T32: rejected | U32: =IF(K32="not answered","not answered",IF(AND(K32="decline",C32="private",N(P32)>0.1),"declined: 10c+ inside the mid",IF(AND(S32<>"",N(S32)<0),"bid short of the reserve",""))) | V32: 382 | W32: =IF(U32="declined: 10c+ inside the mid",P32*ABS(F32),0) | X32: 7 | Z32: run 20261011-094605 (local)
A33: 32 | B33: 127 | C33: private | D33: SELL | E33: CROC | F33: -20000 | G33: 20.62 | H33: 356 | I33: 374 | J33: 371 | K33: decline | L33: -0.0259 | N33: 20.545 | O33: 20.696547 | P33: =IF(OR(G33="",O33=""),"",SIGN(F33)*(O33-G33)) | Q33: 20.79 | S33: =IF(OR(M33="",Q33=""),"",SIGN(F33)*(M33-Q33)) | U33: =IF(K33="not answered","not answered",IF(AND(K33="decline",C33="private",N(P33)>0.1),"declined: 10c+ inside the mid",IF(AND(S33<>"",N(S33)<0),"bid short of the reserve",""))) | V33: 371 | W33: =IF(U33="declined: 10c+ inside the mid",P33*ABS(F33),0) | X33: 7 | Z33: run 20261011-094605 (local)
A34: 33 | B34: 128 | C34: private | D34: BUY | E34: CRZY | F34: 30000 | G34: 10.02 | H34: 365 | I34: 386 | J34: 382 | K34: ACCEPT | L34: 0.0853 | N34: 10.235 | O34: 10.242523 | P34: =IF(OR(G34="",O34=""),"",SIGN(F34)*(O34-G34)) | Q34: 10.09 | S34: =IF(OR(M34="",Q34=""),"",SIGN(F34)*(M34-Q34)) | U34: =IF(K34="not answered","not answered",IF(AND(K34="decline",C34="private",N(P34)>0.1),"declined: 10c+ inside the mid",IF(AND(S34<>"",N(S34)<0),"bid short of the reserve",""))) | V34: 382 | W34: =IF(U34="declined: 10c+ inside the mid",P34*ABS(F34),0) | X34: 7 | Z34: run 20261011-094605 (local)
A35: 34 | B35: 129 | C35: auction | D35: BUY | E35: CRZY | F35: 30000 | H35: 373 | I35: 393 | J35: 390 | K35: ACCEPT | L35: 0.05 | M35: 10.03 | N35: 10.155 | O35: 10.272226 | P35: =IF(OR(G35="",O35=""),"",SIGN(F35)*(O35-G35)) | Q35: 10.2 | S35: =IF(OR(M35="",Q35=""),"",SIGN(F35)*(M35-Q35)) | T35: rejected | U35: =IF(K35="not answered","not answered",IF(AND(K35="decline",C35="private",N(P35)>0.1),"declined: 10c+ inside the mid",IF(AND(S35<>"",N(S35)<0),"bid short of the reserve",""))) | V35: 390 | W35: =IF(U35="declined: 10c+ inside the mid",P35*ABS(F35),0) | X35: 7 | Z35: run 20261011-094605 (local)
A36: 35 | B36: 154 | C36: private | D36: SELL | E36: CROC | F36: -50000 | G36: 20.75 | H36: 412 | I36: 439 | J36: 411 | K36: ACCEPT | L36: 0.1066 | N36: 20.585 | O36: 20.581198 | P36: =IF(OR(G36="",O36=""),"",SIGN(F36)*(O36-G36)) | Q36: 20.72 | S36: =IF(OR(M36="",Q36=""),"",SIGN(F36)*(M36-Q36)) | U36: =IF(K36="not answered","not answered",IF(AND(K36="decline",C36="private",N(P36)>0.1),"declined: 10c+ inside the mid",IF(AND(S36<>"",N(S36)<0),"bid short of the reserve",""))) | V36: 411 | W36: =IF(U36="declined: 10c+ inside the mid",P36*ABS(F36),0) | X36: 7 | Z36: run 20261011-094605 (local)

Sheet Books
A1: Row | B1: Level | C1: Bid size | D1: Bid | E1: Ask | F1: Ask size
A2: 1 | B2: 1 | C2: 6400 | D2: 20.16 | E2: 20.21 | F2: 6400
A3: 1 | B3: 2 | C3: 3200 | D3: 20.15 | E3: 20.22 | F3: 3200
A4: 1 | B4: 3 | C4: 12800 | D4: 20.14 | E4: 20.23 | F4: 3200
A5: 1 | B5: 4 | C5: 12800 | D5: 20.1 | E5: 20.27 | F5: 3200
A6: 1 | B6: 5 | C6: 6400 | D6: 20.08 | E6: 20.29 | F6: 9600
A7: 1 | B7: 6 | C7: 9600 | D7: 20.06 | E7: 20.31 | F7: 6400
A8: 1 | B8: 7 | C8: 3200 | D8: 19.98 | E8: 20.39 | F8: 3200
A9: 1 | B9: 8 | C9: 6400 | D9: 19.95 | E9: 20.42 | F9: 6400
A10: 1 | B10: 9 | C10: 6400 | D10: 19.92 | E10: 20.45 | F10: 9600
A11: 1 | B11: 10 | C11: 3200 | D11: 19.8 | E11: 20.57 | F11: 3200
A12: 1 | B12: 11
A13: 1 | B13: 12
A14: 1 | B14: 13
A15: 1 | B15: 14
A16: 1 | B16: 15
A17: 1 | B17: 16
A18: 1 | B18: 17
A19: 1 | B19: 18
A20: 1 | B20: 19
A21: 1 | B21: 20
A22: 2 | B22: 1 | C22: 2400 | D22: 10.11 | E22: 10.16 | F22: 4800
A23: 2 | B23: 2 | C23: 1200 | D23: 10.1 | E23: 10.17 | F23: 4800
A24: 2 | B24: 3 | C24: 4800 | D24: 10.09 | E24: 10.18 | F24: 3600
A25: 2 | B25: 4 | C25: 3600 | D25: 10.05 | E25: 10.22 | F25: 2400
A26: 2 | B26: 5 | C26: 1200 | D26: 10.03 | E26: 10.24 | F26: 1200
A27: 2 | B27: 6 | C27: 2400 | D27: 10.01 | E27: 10.26 | F27: 1200
A28: 2 | B28: 7 | C28: 3600 | D28: 9.93 | E28: 10.34 | F28: 4800
A29: 2 | B29: 8 | C29: 3600 | D29: 9.9 | E29: 10.37 | F29: 1200
A30: 2 | B30: 9 | C30: 1200 | D30: 9.87 | E30: 10.4 | F30: 2400
A31: 2 | B31: 10 | C31: 1200 | D31: 9.75 | E31: 10.52 | F31: 4800
A32: 2 | B32: 11
A33: 2 | B33: 12
A34: 2 | B34: 13
A35: 2 | B35: 14
A36: 2 | B36: 15
A37: 2 | B37: 16
A38: 2 | B38: 17
A39: 2 | B39: 18
A40: 2 | B40: 19
...

Sheet Tender replay
A1: Current tick | B1: =INDEX(Tenders!$J$1:$J$36,$B$13+1) | G1: Security | H1: 1 | I1: CRZY | P1: 2 | Q1: TAME | X1: 3 | Y1: CROC
A2: Total tick | B2: 420 | G2: 1 | H2: =SUM(I$2:I2) | I2: =IF($B$5=$I$1,INDEX(Books!$C$1:$C$701,2+($B$13-1)*20+G2-1),0) | J2: =IF($B$5=$I$1,INDEX(Books!$D$1:$D$701,2+($B$13-1)*20+G2-1),0) | K2: =IF($B$5=$I$1,INDEX(Books!$E$1:$E$701,2+($B$13-1)*20+G2-1),0) | L2: =IF($B$5=$I$1,INDEX(Books!$F$1:$F$701,2+($B$13-1)*20+G2-1),0) | M2: =SUM(L$2:L2) | O2: 1 | P2: =SUM(Q$2:Q2) | Q2: =IF($B$5=$Q$1,INDEX(Books!$C$1:$C$701,2+($B$13-1)*20+O2-1),0) | R2: =IF($B$5=$Q$1,INDEX(Books!$D$1:$D$701,2+($B$13-1)*20+O2-1),0) | S2: =IF($B$5=$Q$1,INDEX(Books!$E$1:$E$701,2+($B$13-1)*20+O2-1),0) | T2: =IF($B$5=$Q$1,INDEX(Books!$F$1:$F$701,2+($B$13-1)*20+O2-1),0) | U2: =SUM(T$2:T2) | W2: 1 | X2: =SUM(Y$2:Y2) | Y2: =IF($B$5=$Y$1,INDEX(Books!$C$1:$C$701,2+($B$13-1)*20+W2-1),0) | Z2: =IF($B$5=$Y$1,INDEX(Books!$D$1:$D$701,2+($B$13-1)*20+W2-1),0) | AA2: =IF($B$5=$Y$1,INDEX(Books!$E$1:$E$701,2+($B$13-1)*20+W2-1),0) | AB2: =IF($B$5=$Y$1,INDEX(Books!$F$1:$F$701,2+($B$13-1)*20+W2-1),0) | AC2: =SUM(AB$2:AB2)
A3: Tenders | G3: 2 | H3: =SUM(I$2:I3) | I3: =IF($B$5=$I$1,INDEX(Books!$C$1:$C$701,2+($B$13-1)*20+G3-1),0) | J3: =IF($B$5=$I$1,INDEX(Books!$D$1:$D$701,2+($B$13-1)*20+G3-1),0) | K3: =IF($B$5=$I$1,INDEX(Books!$E$1:$E$701,2+($B$13-1)*20+G3-1),0) | L3: =IF($B$5=$I$1,INDEX(Books!$F$1:$F$701,2+($B$13-1)*20+G3-1),0) | M3: =SUM(L$2:L3) | O3: 2 | P3: =SUM(Q$2:Q3) | Q3: =IF($B$5=$Q$1,INDEX(Books!$C$1:$C$701,2+($B$13-1)*20+O3-1),0) | R3: =IF($B$5=$Q$1,INDEX(Books!$D$1:$D$701,2+($B$13-1)*20+O3-1),0) | S3: =IF($B$5=$Q$1,INDEX(Books!$E$1:$E$701,2+($B$13-1)*20+O3-1),0) | T3: =IF($B$5=$Q$1,INDEX(Books!$F$1:$F$701,2+($B$13-1)*20+O3-1),0) | U3: =SUM(T$2:T3) | W3: 2 | X3: =SUM(Y$2:Y3) | Y3: =IF($B$5=$Y$1,INDEX(Books!$C$1:$C$701,2+($B$13-1)*20+W3-1),0) | Z3: =IF($B$5=$Y$1,INDEX(Books!$D$1:$D$701,2+($B$13-1)*20+W3-1),0) | AA3: =IF($B$5=$Y$1,INDEX(Books!$E$1:$E$701,2+($B$13-1)*20+W3-1),0) | AB3: =IF($B$5=$Y$1,INDEX(Books!$F$1:$F$701,2+($B$13-1)*20+W3-1),0) | AC3: =SUM(AB$2:AB3)
A4: Tender ID | B4: =INDEX(Tenders!$B$1:$B$36,$B$13+1) | D4: Full text | E4: =IF(B4="","",B4&","&B5&","&B7&","&B8&","&B9&","&B10) | G4: 3 | H4: =SUM(I$2:I4) | I4: =IF($B$5=$I$1,INDEX(Books!$C$1:$C$701,2+($B$13-1)*20+G4-1),0) | J4: =IF($B$5=$I$1,INDEX(Books!$D$1:$D$701,2+($B$13-1)*20+G4-1),0) | K4: =IF($B$5=$I$1,INDEX(Books!$E$1:$E$701,2+($B$13-1)*20+G4-1),0) | L4: =IF($B$5=$I$1,INDEX(Books!$F$1:$F$701,2+($B$13-1)*20+G4-1),0) | M4: =SUM(L$2:L4) | O4: 3 | P4: =SUM(Q$2:Q4) | Q4: =IF($B$5=$Q$1,INDEX(Books!$C$1:$C$701,2+($B$13-1)*20+O4-1),0) | R4: =IF($B$5=$Q$1,INDEX(Books!$D$1:$D$701,2+($B$13-1)*20+O4-1),0) | S4: =IF($B$5=$Q$1,INDEX(Books!$E$1:$E$701,2+($B$13-1)*20+O4-1),0) | T4: =IF($B$5=$Q$1,INDEX(Books!$F$1:$F$701,2+($B$13-1)*20+O4-1),0) | U4: =SUM(T$2:T4) | W4: 3 | X4: =SUM(Y$2:Y4) | Y4: =IF($B$5=$Y$1,INDEX(Books!$C$1:$C$701,2+($B$13-1)*20+W4-1),0) | Z4: =IF($B$5=$Y$1,INDEX(Books!$D$1:$D$701,2+($B$13-1)*20+W4-1),0) | AA4: =IF($B$5=$Y$1,INDEX(Books!$E$1:$E$701,2+($B$13-1)*20+W4-1),0) | AB4: =IF($B$5=$Y$1,INDEX(Books!$F$1:$F$701,2+($B$13-1)*20+W4-1),0) | AC4: =SUM(AB$2:AB4)
A5: Security | B5: =INDEX(Tenders!$E$1:$E$36,$B$13+1) | G5: 4 | H5: =SUM(I$2:I5) | I5: =IF($B$5=$I$1,INDEX(Books!$C$1:$C$701,2+($B$13-1)*20+G5-1),0) | J5: =IF($B$5=$I$1,INDEX(Books!$D$1:$D$701,2+($B$13-1)*20+G5-1),0) | K5: =IF($B$5=$I$1,INDEX(Books!$E$1:$E$701,2+($B$13-1)*20+G5-1),0) | L5: =IF($B$5=$I$1,INDEX(Books!$F$1:$F$701,2+($B$13-1)*20+G5-1),0) | M5: =SUM(L$2:L5) | O5: 4 | P5: =SUM(Q$2:Q5) | Q5: =IF($B$5=$Q$1,INDEX(Books!$C$1:$C$701,2+($B$13-1)*20+O5-1),0) | R5: =IF($B$5=$Q$1,INDEX(Books!$D$1:$D$701,2+($B$13-1)*20+O5-1),0) | S5: =IF($B$5=$Q$1,INDEX(Books!$E$1:$E$701,2+($B$13-1)*20+O5-1),0) | T5: =IF($B$5=$Q$1,INDEX(Books!$F$1:$F$701,2+($B$13-1)*20+O5-1),0) | U5: =SUM(T$2:T5) | W5: 4 | X5: =SUM(Y$2:Y5) | Y5: =IF($B$5=$Y$1,INDEX(Books!$C$1:$C$701,2+($B$13-1)*20+W5-1),0) | Z5: =IF($B$5=$Y$1,INDEX(Books!$D$1:$D$701,2+($B$13-1)*20+W5-1),0) | AA5: =IF($B$5=$Y$1,INDEX(Books!$E$1:$E$701,2+($B$13-1)*20+W5-1),0) | AB5: =IF($B$5=$Y$1,INDEX(Books!$F$1:$F$701,2+($B$13-1)*20+W5-1),0) | AC5: =SUM(AB$2:AB5)
A6: Sec Number | B6: =IF(B5="","",IF(B5="CRZY",1,IF(B5="TAME",2,3))) | G6: 5 | H6: =SUM(I$2:I6) | I6: =IF($B$5=$I$1,INDEX(Books!$C$1:$C$701,2+($B$13-1)*20+G6-1),0) | J6: =IF($B$5=$I$1,INDEX(Books!$D$1:$D$701,2+($B$13-1)*20+G6-1),0) | K6: =IF($B$5=$I$1,INDEX(Books!$E$1:$E$701,2+($B$13-1)*20+G6-1),0) | L6: =IF($B$5=$I$1,INDEX(Books!$F$1:$F$701,2+($B$13-1)*20+G6-1),0) | M6: =SUM(L$2:L6) | O6: 5 | P6: =SUM(Q$2:Q6) | Q6: =IF($B$5=$Q$1,INDEX(Books!$C$1:$C$701,2+($B$13-1)*20+O6-1),0) | R6: =IF($B$5=$Q$1,INDEX(Books!$D$1:$D$701,2+($B$13-1)*20+O6-1),0) | S6: =IF($B$5=$Q$1,INDEX(Books!$E$1:$E$701,2+($B$13-1)*20+O6-1),0) | T6: =IF($B$5=$Q$1,INDEX(Books!$F$1:$F$701,2+($B$13-1)*20+O6-1),0) | U6: =SUM(T$2:T6) | W6: 5 | X6: =SUM(Y$2:Y6) | Y6: =IF($B$5=$Y$1,INDEX(Books!$C$1:$C$701,2+($B$13-1)*20+W6-1),0) | Z6: =IF($B$5=$Y$1,INDEX(Books!$D$1:$D$701,2+($B$13-1)*20+W6-1),0) | AA6: =IF($B$5=$Y$1,INDEX(Books!$E$1:$E$701,2+($B$13-1)*20+W6-1),0) | AB6: =IF($B$5=$Y$1,INDEX(Books!$F$1:$F$701,2+($B$13-1)*20+W6-1),0) | AC6: =SUM(AB$2:AB6)
A7: Volume | B7: =INDEX(Tenders!$F$1:$F$36,$B$13+1) | C7: =IFERROR(IF(B7>0,"BUY",IF(B7<0,"SELL","")),"") | G7: 6 | H7: =SUM(I$2:I7) | I7: =IF($B$5=$I$1,INDEX(Books!$C$1:$C$701,2+($B$13-1)*20+G7-1),0) | J7: =IF($B$5=$I$1,INDEX(Books!$D$1:$D$701,2+($B$13-1)*20+G7-1),0) | K7: =IF($B$5=$I$1,INDEX(Books!$E$1:$E$701,2+($B$13-1)*20+G7-1),0) | L7: =IF($B$5=$I$1,INDEX(Books!$F$1:$F$701,2+($B$13-1)*20+G7-1),0) | M7: =SUM(L$2:L7) | O7: 6 | P7: =SUM(Q$2:Q7) | Q7: =IF($B$5=$Q$1,INDEX(Books!$C$1:$C$701,2+($B$13-1)*20+O7-1),0) | R7: =IF($B$5=$Q$1,INDEX(Books!$D$1:$D$701,2+($B$13-1)*20+O7-1),0) | S7: =IF($B$5=$Q$1,INDEX(Books!$E$1:$E$701,2+($B$13-1)*20+O7-1),0) | T7: =IF($B$5=$Q$1,INDEX(Books!$F$1:$F$701,2+($B$13-1)*20+O7-1),0) | U7: =SUM(T$2:T7) | W7: 6 | X7: =SUM(Y$2:Y7) | Y7: =IF($B$5=$Y$1,INDEX(Books!$C$1:$C$701,2+($B$13-1)*20+W7-1),0) | Z7: =IF($B$5=$Y$1,INDEX(Books!$D$1:$D$701,2+($B$13-1)*20+W7-1),0) | AA7: =IF($B$5=$Y$1,INDEX(Books!$E$1:$E$701,2+($B$13-1)*20+W7-1),0) | AB7: =IF($B$5=$Y$1,INDEX(Books!$F$1:$F$701,2+($B$13-1)*20+W7-1),0) | AC7: =SUM(AB$2:AB7)
A8: Price | B8: =IF(INDEX(Tenders!$G$1:$G$36,$B$13+1)="","",INDEX(Tenders!$G$1:$G$36,$B$13+1)) | G8: 7 | H8: =SUM(I$2:I8) | I8: =IF($B$5=$I$1,INDEX(Books!$C$1:$C$701,2+($B$13-1)*20+G8-1),0) | J8: =IF($B$5=$I$1,INDEX(Books!$D$1:$D$701,2+($B$13-1)*20+G8-1),0) | K8: =IF($B$5=$I$1,INDEX(Books!$E$1:$E$701,2+($B$13-1)*20+G8-1),0) | L8: =IF($B$5=$I$1,INDEX(Books!$F$1:$F$701,2+($B$13-1)*20+G8-1),0) | M8: =SUM(L$2:L8) | O8: 7 | P8: =SUM(Q$2:Q8) | Q8: =IF($B$5=$Q$1,INDEX(Books!$C$1:$C$701,2+($B$13-1)*20+O8-1),0) | R8: =IF($B$5=$Q$1,INDEX(Books!$D$1:$D$701,2+($B$13-1)*20+O8-1),0) | S8: =IF($B$5=$Q$1,INDEX(Books!$E$1:$E$701,2+($B$13-1)*20+O8-1),0) | T8: =IF($B$5=$Q$1,INDEX(Books!$F$1:$F$701,2+($B$13-1)*20+O8-1),0) | U8: =SUM(T$2:T8) | W8: 7 | X8: =SUM(Y$2:Y8) | Y8: =IF($B$5=$Y$1,INDEX(Books!$C$1:$C$701,2+($B$13-1)*20+W8-1),0) | Z8: =IF($B$5=$Y$1,INDEX(Books!$D$1:$D$701,2+($B$13-1)*20+W8-1),0) | AA8: =IF($B$5=$Y$1,INDEX(Books!$E$1:$E$701,2+($B$13-1)*20+W8-1),0) | AB8: =IF($B$5=$Y$1,INDEX(Books!$F$1:$F$701,2+($B$13-1)*20+W8-1),0) | AC8: =SUM(AB$2:AB8)
A9: Tick received | B9: =INDEX(Tenders!$H$1:$H$36,$B$13+1) | G9: 8 | H9: =SUM(I$2:I9) | I9: =IF($B$5=$I$1,INDEX(Books!$C$1:$C$701,2+($B$13-1)*20+G9-1),0) | J9: =IF($B$5=$I$1,INDEX(Books!$D$1:$D$701,2+($B$13-1)*20+G9-1),0) | K9: =IF($B$5=$I$1,INDEX(Books!$E$1:$E$701,2+($B$13-1)*20+G9-1),0) | L9: =IF($B$5=$I$1,INDEX(Books!$F$1:$F$701,2+($B$13-1)*20+G9-1),0) | M9: =SUM(L$2:L9) | O9: 8 | P9: =SUM(Q$2:Q9) | Q9: =IF($B$5=$Q$1,INDEX(Books!$C$1:$C$701,2+($B$13-1)*20+O9-1),0) | R9: =IF($B$5=$Q$1,INDEX(Books!$D$1:$D$701,2+($B$13-1)*20+O9-1),0) | S9: =IF($B$5=$Q$1,INDEX(Books!$E$1:$E$701,2+($B$13-1)*20+O9-1),0) | T9: =IF($B$5=$Q$1,INDEX(Books!$F$1:$F$701,2+($B$13-1)*20+O9-1),0) | U9: =SUM(T$2:T9) | W9: 8 | X9: =SUM(Y$2:Y9) | Y9: =IF($B$5=$Y$1,INDEX(Books!$C$1:$C$701,2+($B$13-1)*20+W9-1),0) | Z9: =IF($B$5=$Y$1,INDEX(Books!$D$1:$D$701,2+($B$13-1)*20+W9-1),0) | AA9: =IF($B$5=$Y$1,INDEX(Books!$E$1:$E$701,2+($B$13-1)*20+W9-1),0) | AB9: =IF($B$5=$Y$1,INDEX(Books!$F$1:$F$701,2+($B$13-1)*20+W9-1),0) | AC9: =SUM(AB$2:AB9)
A10: Tick expired | B10: =INDEX(Tenders!$I$1:$I$36,$B$13+1) | G10: 9 | H10: =SUM(I$2:I10) | I10: =IF($B$5=$I$1,INDEX(Books!$C$1:$C$701,2+($B$13-1)*20+G10-1),0) | J10: =IF($B$5=$I$1,INDEX(Books!$D$1:$D$701,2+($B$13-1)*20+G10-1),0) | K10: =IF($B$5=$I$1,INDEX(Books!$E$1:$E$701,2+($B$13-1)*20+G10-1),0) | L10: =IF($B$5=$I$1,INDEX(Books!$F$1:$F$701,2+($B$13-1)*20+G10-1),0) | M10: =SUM(L$2:L10) | O10: 9 | P10: =SUM(Q$2:Q10) | Q10: =IF($B$5=$Q$1,INDEX(Books!$C$1:$C$701,2+($B$13-1)*20+O10-1),0) | R10: =IF($B$5=$Q$1,INDEX(Books!$D$1:$D$701,2+($B$13-1)*20+O10-1),0) | S10: =IF($B$5=$Q$1,INDEX(Books!$E$1:$E$701,2+($B$13-1)*20+O10-1),0) | T10: =IF($B$5=$Q$1,INDEX(Books!$F$1:$F$701,2+($B$13-1)*20+O10-1),0) | U10: =SUM(T$2:T10) | W10: 9 | X10: =SUM(Y$2:Y10) | Y10: =IF($B$5=$Y$1,INDEX(Books!$C$1:$C$701,2+($B$13-1)*20+W10-1),0) | Z10: =IF($B$5=$Y$1,INDEX(Books!$D$1:$D$701,2+($B$13-1)*20+W10-1),0) | AA10: =IF($B$5=$Y$1,INDEX(Books!$E$1:$E$701,2+($B$13-1)*20+W10-1),0) | AB10: =IF($B$5=$Y$1,INDEX(Books!$F$1:$F$701,2+($B$13-1)*20+W10-1),0) | AC10: =SUM(AB$2:AB10)
A11: Ticks left to decide | B11: =IF(OR(B10="",B1=""),"",B10-B1) | G11: 10 | H11: =SUM(I$2:I11) | I11: =IF($B$5=$I$1,INDEX(Books!$C$1:$C$701,2+($B$13-1)*20+G11-1),0) | J11: =IF($B$5=$I$1,INDEX(Books!$D$1:$D$701,2+($B$13-1)*20+G11-1),0) | K11: =IF($B$5=$I$1,INDEX(Books!$E$1:$E$701,2+($B$13-1)*20+G11-1),0) | L11: =IF($B$5=$I$1,INDEX(Books!$F$1:$F$701,2+($B$13-1)*20+G11-1),0) | M11: =SUM(L$2:L11) | O11: 10 | P11: =SUM(Q$2:Q11) | Q11: =IF($B$5=$Q$1,INDEX(Books!$C$1:$C$701,2+($B$13-1)*20+O11-1),0) | R11: =IF($B$5=$Q$1,INDEX(Books!$D$1:$D$701,2+($B$13-1)*20+O11-1),0) | S11: =IF($B$5=$Q$1,INDEX(Books!$E$1:$E$701,2+($B$13-1)*20+O11-1),0) | T11: =IF($B$5=$Q$1,INDEX(Books!$F$1:$F$701,2+($B$13-1)*20+O11-1),0) | U11: =SUM(T$2:T11) | W11: 10 | X11: =SUM(Y$2:Y11) | Y11: =IF($B$5=$Y$1,INDEX(Books!$C$1:$C$701,2+($B$13-1)*20+W11-1),0) | Z11: =IF($B$5=$Y$1,INDEX(Books!$D$1:$D$701,2+($B$13-1)*20+W11-1),0) | AA11: =IF($B$5=$Y$1,INDEX(Books!$E$1:$E$701,2+($B$13-1)*20+W11-1),0) | AB11: =IF($B$5=$Y$1,INDEX(Books!$F$1:$F$701,2+($B$13-1)*20+W11-1),0) | AC11: =SUM(AB$2:AB11)
G12: 11 | H12: =SUM(I$2:I12) | I12: =IF($B$5=$I$1,INDEX(Books!$C$1:$C$701,2+($B$13-1)*20+G12-1),0) | J12: =IF($B$5=$I$1,INDEX(Books!$D$1:$D$701,2+($B$13-1)*20+G12-1),0) | K12: =IF($B$5=$I$1,INDEX(Books!$E$1:$E$701,2+($B$13-1)*20+G12-1),0) | L12: =IF($B$5=$I$1,INDEX(Books!$F$1:$F$701,2+($B$13-1)*20+G12-1),0) | M12: =SUM(L$2:L12) | O12: 11 | P12: =SUM(Q$2:Q12) | Q12: =IF($B$5=$Q$1,INDEX(Books!$C$1:$C$701,2+($B$13-1)*20+O12-1),0) | R12: =IF($B$5=$Q$1,INDEX(Books!$D$1:$D$701,2+($B$13-1)*20+O12-1),0) | S12: =IF($B$5=$Q$1,INDEX(Books!$E$1:$E$701,2+($B$13-1)*20+O12-1),0) | T12: =IF($B$5=$Q$1,INDEX(Books!$F$1:$F$701,2+($B$13-1)*20+O12-1),0) | U12: =SUM(T$2:T12) | W12: 11 | X12: =SUM(Y$2:Y12) | Y12: =IF($B$5=$Y$1,INDEX(Books!$C$1:$C$701,2+($B$13-1)*20+W12-1),0) | Z12: =IF($B$5=$Y$1,INDEX(Books!$D$1:$D$701,2+($B$13-1)*20+W12-1),0) | AA12: =IF($B$5=$Y$1,INDEX(Books!$E$1:$E$701,2+($B$13-1)*20+W12-1),0) | AB12: =IF($B$5=$Y$1,INDEX(Books!$F$1:$F$701,2+($B$13-1)*20+W12-1),0) | AC12: =SUM(AB$2:AB12)
A13: Show Tenders row (type a number) | B13: 1 | G13: 12 | H13: =SUM(I$2:I13) | I13: =IF($B$5=$I$1,INDEX(Books!$C$1:$C$701,2+($B$13-1)*20+G13-1),0) | J13: =IF($B$5=$I$1,INDEX(Books!$D$1:$D$701,2+($B$13-1)*20+G13-1),0) | K13: =IF($B$5=$I$1,INDEX(Books!$E$1:$E$701,2+($B$13-1)*20+G13-1),0) | L13: =IF($B$5=$I$1,INDEX(Books!$F$1:$F$701,2+($B$13-1)*20+G13-1),0) | M13: =SUM(L$2:L13) | O13: 12 | P13: =SUM(Q$2:Q13) | Q13: =IF($B$5=$Q$1,INDEX(Books!$C$1:$C$701,2+($B$13-1)*20+O13-1),0) | R13: =IF($B$5=$Q$1,INDEX(Books!$D$1:$D$701,2+($B$13-1)*20+O13-1),0) | S13: =IF($B$5=$Q$1,INDEX(Books!$E$1:$E$701,2+($B$13-1)*20+O13-1),0) | T13: =IF($B$5=$Q$1,INDEX(Books!$F$1:$F$701,2+($B$13-1)*20+O13-1),0) | U13: =SUM(T$2:T13) | W13: 12 | X13: =SUM(Y$2:Y13) | Y13: =IF($B$5=$Y$1,INDEX(Books!$C$1:$C$701,2+($B$13-1)*20+W13-1),0) | Z13: =IF($B$5=$Y$1,INDEX(Books!$D$1:$D$701,2+($B$13-1)*20+W13-1),0) | AA13: =IF($B$5=$Y$1,INDEX(Books!$E$1:$E$701,2+($B$13-1)*20+W13-1),0) | AB13: =IF($B$5=$Y$1,INDEX(Books!$F$1:$F$701,2+($B$13-1)*20+W13-1),0) | AC13: =SUM(AB$2:AB13)
A14: Source / seed of that row | B14: =INDEX(Tenders!$Z$1:$Z$36,$B$13+1)&" / seed "&INDEX(Tenders!$X$1:$X$36,$B$13+1) | G14: 13 | H14: =SUM(I$2:I14) | I14: =IF($B$5=$I$1,INDEX(Books!$C$1:$C$701,2+($B$13-1)*20+G14-1),0) | J14: =IF($B$5=$I$1,INDEX(Books!$D$1:$D$701,2+($B$13-1)*20+G14-1),0) | K14: =IF($B$5=$I$1,INDEX(Books!$E$1:$E$701,2+($B$13-1)*20+G14-1),0) | L14: =IF($B$5=$I$1,INDEX(Books!$F$1:$F$701,2+($B$13-1)*20+G14-1),0) | M14: =SUM(L$2:L14) | O14: 13 | P14: =SUM(Q$2:Q14) | Q14: =IF($B$5=$Q$1,INDEX(Books!$C$1:$C$701,2+($B$13-1)*20+O14-1),0) | R14: =IF($B$5=$Q$1,INDEX(Books!$D$1:$D$701,2+($B$13-1)*20+O14-1),0) | S14: =IF($B$5=$Q$1,INDEX(Books!$E$1:$E$701,2+($B$13-1)*20+O14-1),0) | T14: =IF($B$5=$Q$1,INDEX(Books!$F$1:$F$701,2+($B$13-1)*20+O14-1),0) | U14: =SUM(T$2:T14) | W14: 13 | X14: =SUM(Y$2:Y14) | Y14: =IF($B$5=$Y$1,INDEX(Books!$C$1:$C$701,2+($B$13-1)*20+W14-1),0) | Z14: =IF($B$5=$Y$1,INDEX(Books!$D$1:$D$701,2+($B$13-1)*20+W14-1),0) | AA14: =IF($B$5=$Y$1,INDEX(Books!$E$1:$E$701,2+($B$13-1)*20+W14-1),0) | AB14: =IF($B$5=$Y$1,INDEX(Books!$F$1:$F$701,2+($B$13-1)*20+W14-1),0) | AC14: =SUM(AB$2:AB14)
G15: 14 | H15: =SUM(I$2:I15) | I15: =IF($B$5=$I$1,INDEX(Books!$C$1:$C$701,2+($B$13-1)*20+G15-1),0) | J15: =IF($B$5=$I$1,INDEX(Books!$D$1:$D$701,2+($B$13-1)*20+G15-1),0) | K15: =IF($B$5=$I$1,INDEX(Books!$E$1:$E$701,2+($B$13-1)*20+G15-1),0) | L15: =IF($B$5=$I$1,INDEX(Books!$F$1:$F$701,2+($B$13-1)*20+G15-1),0) | M15: =SUM(L$2:L15) | O15: 14 | P15: =SUM(Q$2:Q15) | Q15: =IF($B$5=$Q$1,INDEX(Books!$C$1:$C$701,2+($B$13-1)*20+O15-1),0) | R15: =IF($B$5=$Q$1,INDEX(Books!$D$1:$D$701,2+($B$13-1)*20+O15-1),0) | S15: =IF($B$5=$Q$1,INDEX(Books!$E$1:$E$701,2+($B$13-1)*20+O15-1),0) | T15: =IF($B$5=$Q$1,INDEX(Books!$F$1:$F$701,2+($B$13-1)*20+O15-1),0) | U15: =SUM(T$2:T15) | W15: 14 | X15: =SUM(Y$2:Y15) | Y15: =IF($B$5=$Y$1,INDEX(Books!$C$1:$C$701,2+($B$13-1)*20+W15-1),0) | Z15: =IF($B$5=$Y$1,INDEX(Books!$D$1:$D$701,2+($B$13-1)*20+W15-1),0) | AA15: =IF($B$5=$Y$1,INDEX(Books!$E$1:$E$701,2+($B$13-1)*20+W15-1),0) | AB15: =IF($B$5=$Y$1,INDEX(Books!$F$1:$F$701,2+($B$13-1)*20+W15-1),0) | AC15: =SUM(AB$2:AB15)
G16: 15 | H16: =SUM(I$2:I16) | I16: =IF($B$5=$I$1,INDEX(Books!$C$1:$C$701,2+($B$13-1)*20+G16-1),0) | J16: =IF($B$5=$I$1,INDEX(Books!$D$1:$D$701,2+($B$13-1)*20+G16-1),0) | K16: =IF($B$5=$I$1,INDEX(Books!$E$1:$E$701,2+($B$13-1)*20+G16-1),0) | L16: =IF($B$5=$I$1,INDEX(Books!$F$1:$F$701,2+($B$13-1)*20+G16-1),0) | M16: =SUM(L$2:L16) | O16: 15 | P16: =SUM(Q$2:Q16) | Q16: =IF($B$5=$Q$1,INDEX(Books!$C$1:$C$701,2+($B$13-1)*20+O16-1),0) | R16: =IF($B$5=$Q$1,INDEX(Books!$D$1:$D$701,2+($B$13-1)*20+O16-1),0) | S16: =IF($B$5=$Q$1,INDEX(Books!$E$1:$E$701,2+($B$13-1)*20+O16-1),0) | T16: =IF($B$5=$Q$1,INDEX(Books!$F$1:$F$701,2+($B$13-1)*20+O16-1),0) | U16: =SUM(T$2:T16) | W16: 15 | X16: =SUM(Y$2:Y16) | Y16: =IF($B$5=$Y$1,INDEX(Books!$C$1:$C$701,2+($B$13-1)*20+W16-1),0) | Z16: =IF($B$5=$Y$1,INDEX(Books!$D$1:$D$701,2+($B$13-1)*20+W16-1),0) | AA16: =IF($B$5=$Y$1,INDEX(Books!$E$1:$E$701,2+($B$13-1)*20+W16-1),0) | AB16: =IF($B$5=$Y$1,INDEX(Books!$F$1:$F$701,2+($B$13-1)*20+W16-1),0) | AC16: =SUM(AB$2:AB16)
G17: 16 | H17: =SUM(I$2:I17) | I17: =IF($B$5=$I$1,INDEX(Books!$C$1:$C$701,2+($B$13-1)*20+G17-1),0) | J17: =IF($B$5=$I$1,INDEX(Books!$D$1:$D$701,2+($B$13-1)*20+G17-1),0) | K17: =IF($B$5=$I$1,INDEX(Books!$E$1:$E$701,2+($B$13-1)*20+G17-1),0) | L17: =IF($B$5=$I$1,INDEX(Books!$F$1:$F$701,2+($B$13-1)*20+G17-1),0) | M17: =SUM(L$2:L17) | O17: 16 | P17: =SUM(Q$2:Q17) | Q17: =IF($B$5=$Q$1,INDEX(Books!$C$1:$C$701,2+($B$13-1)*20+O17-1),0) | R17: =IF($B$5=$Q$1,INDEX(Books!$D$1:$D$701,2+($B$13-1)*20+O17-1),0) | S17: =IF($B$5=$Q$1,INDEX(Books!$E$1:$E$701,2+($B$13-1)*20+O17-1),0) | T17: =IF($B$5=$Q$1,INDEX(Books!$F$1:$F$701,2+($B$13-1)*20+O17-1),0) | U17: =SUM(T$2:T17) | W17: 16 | X17: =SUM(Y$2:Y17) | Y17: =IF($B$5=$Y$1,INDEX(Books!$C$1:$C$701,2+($B$13-1)*20+W17-1),0) | Z17: =IF($B$5=$Y$1,INDEX(Books!$D$1:$D$701,2+($B$13-1)*20+W17-1),0) | AA17: =IF($B$5=$Y$1,INDEX(Books!$E$1:$E$701,2+($B$13-1)*20+W17-1),0) | AB17: =IF($B$5=$Y$1,INDEX(Books!$F$1:$F$701,2+($B$13-1)*20+W17-1),0) | AC17: =SUM(AB$2:AB17)
G18: 17 | H18: =SUM(I$2:I18) | I18: =IF($B$5=$I$1,INDEX(Books!$C$1:$C$701,2+($B$13-1)*20+G18-1),0) | J18: =IF($B$5=$I$1,INDEX(Books!$D$1:$D$701,2+($B$13-1)*20+G18-1),0) | K18: =IF($B$5=$I$1,INDEX(Books!$E$1:$E$701,2+($B$13-1)*20+G18-1),0) | L18: =IF($B$5=$I$1,INDEX(Books!$F$1:$F$701,2+($B$13-1)*20+G18-1),0) | M18: =SUM(L$2:L18) | O18: 17 | P18: =SUM(Q$2:Q18) | Q18: =IF($B$5=$Q$1,INDEX(Books!$C$1:$C$701,2+($B$13-1)*20+O18-1),0) | R18: =IF($B$5=$Q$1,INDEX(Books!$D$1:$D$701,2+($B$13-1)*20+O18-1),0) | S18: =IF($B$5=$Q$1,INDEX(Books!$E$1:$E$701,2+($B$13-1)*20+O18-1),0) | T18: =IF($B$5=$Q$1,INDEX(Books!$F$1:$F$701,2+($B$13-1)*20+O18-1),0) | U18: =SUM(T$2:T18) | W18: 17 | X18: =SUM(Y$2:Y18) | Y18: =IF($B$5=$Y$1,INDEX(Books!$C$1:$C$701,2+($B$13-1)*20+W18-1),0) | Z18: =IF($B$5=$Y$1,INDEX(Books!$D$1:$D$701,2+($B$13-1)*20+W18-1),0) | AA18: =IF($B$5=$Y$1,INDEX(Books!$E$1:$E$701,2+($B$13-1)*20+W18-1),0) | AB18: =IF($B$5=$Y$1,INDEX(Books!$F$1:$F$701,2+($B$13-1)*20+W18-1),0) | AC18: =SUM(AB$2:AB18)
G19: 18 | H19: =SUM(I$2:I19) | I19: =IF($B$5=$I$1,INDEX(Books!$C$1:$C$701,2+($B$13-1)*20+G19-1),0) | J19: =IF($B$5=$I$1,INDEX(Books!$D$1:$D$701,2+($B$13-1)*20+G19-1),0) | K19: =IF($B$5=$I$1,INDEX(Books!$E$1:$E$701,2+($B$13-1)*20+G19-1),0) | L19: =IF($B$5=$I$1,INDEX(Books!$F$1:$F$701,2+($B$13-1)*20+G19-1),0) | M19: =SUM(L$2:L19) | O19: 18 | P19: =SUM(Q$2:Q19) | Q19: =IF($B$5=$Q$1,INDEX(Books!$C$1:$C$701,2+($B$13-1)*20+O19-1),0) | R19: =IF($B$5=$Q$1,INDEX(Books!$D$1:$D$701,2+($B$13-1)*20+O19-1),0) | S19: =IF($B$5=$Q$1,INDEX(Books!$E$1:$E$701,2+($B$13-1)*20+O19-1),0) | T19: =IF($B$5=$Q$1,INDEX(Books!$F$1:$F$701,2+($B$13-1)*20+O19-1),0) | U19: =SUM(T$2:T19) | W19: 18 | X19: =SUM(Y$2:Y19) | Y19: =IF($B$5=$Y$1,INDEX(Books!$C$1:$C$701,2+($B$13-1)*20+W19-1),0) | Z19: =IF($B$5=$Y$1,INDEX(Books!$D$1:$D$701,2+($B$13-1)*20+W19-1),0) | AA19: =IF($B$5=$Y$1,INDEX(Books!$E$1:$E$701,2+($B$13-1)*20+W19-1),0) | AB19: =IF($B$5=$Y$1,INDEX(Books!$F$1:$F$701,2+($B$13-1)*20+W19-1),0) | AC19: =SUM(AB$2:AB19)
G20: 19 | H20: =SUM(I$2:I20) | I20: =IF($B$5=$I$1,INDEX(Books!$C$1:$C$701,2+($B$13-1)*20+G20-1),0) | J20: =IF($B$5=$I$1,INDEX(Books!$D$1:$D$701,2+($B$13-1)*20+G20-1),0) | K20: =IF($B$5=$I$1,INDEX(Books!$E$1:$E$701,2+($B$13-1)*20+G20-1),0) | L20: =IF($B$5=$I$1,INDEX(Books!$F$1:$F$701,2+($B$13-1)*20+G20-1),0) | M20: =SUM(L$2:L20) | O20: 19 | P20: =SUM(Q$2:Q20) | Q20: =IF($B$5=$Q$1,INDEX(Books!$C$1:$C$701,2+($B$13-1)*20+O20-1),0) | R20: =IF($B$5=$Q$1,INDEX(Books!$D$1:$D$701,2+($B$13-1)*20+O20-1),0) | S20: =IF($B$5=$Q$1,INDEX(Books!$E$1:$E$701,2+($B$13-1)*20+O20-1),0) | T20: =IF($B$5=$Q$1,INDEX(Books!$F$1:$F$701,2+($B$13-1)*20+O20-1),0) | U20: =SUM(T$2:T20) | W20: 19 | X20: =SUM(Y$2:Y20) | Y20: =IF($B$5=$Y$1,INDEX(Books!$C$1:$C$701,2+($B$13-1)*20+W20-1),0) | Z20: =IF($B$5=$Y$1,INDEX(Books!$D$1:$D$701,2+($B$13-1)*20+W20-1),0) | AA20: =IF($B$5=$Y$1,INDEX(Books!$E$1:$E$701,2+($B$13-1)*20+W20-1),0) | AB20: =IF($B$5=$Y$1,INDEX(Books!$F$1:$F$701,2+($B$13-1)*20+W20-1),0) | AC20: =SUM(AB$2:AB20)
G21: 20 | H21: =SUM(I$2:I21) | I21: =IF($B$5=$I$1,INDEX(Books!$C$1:$C$701,2+($B$13-1)*20+G21-1),0) | J21: =IF($B$5=$I$1,INDEX(Books!$D$1:$D$701,2+($B$13-1)*20+G21-1),0) | K21: =IF($B$5=$I$1,INDEX(Books!$E$1:$E$701,2+($B$13-1)*20+G21-1),0) | L21: =IF($B$5=$I$1,INDEX(Books!$F$1:$F$701,2+($B$13-1)*20+G21-1),0) | M21: =SUM(L$2:L21) | O21: 20 | P21: =SUM(Q$2:Q21) | Q21: =IF($B$5=$Q$1,INDEX(Books!$C$1:$C$701,2+($B$13-1)*20+O21-1),0) | R21: =IF($B$5=$Q$1,INDEX(Books!$D$1:$D$701,2+($B$13-1)*20+O21-1),0) | S21: =IF($B$5=$Q$1,INDEX(Books!$E$1:$E$701,2+($B$13-1)*20+O21-1),0) | T21: =IF($B$5=$Q$1,INDEX(Books!$F$1:$F$701,2+($B$13-1)*20+O21-1),0) | U21: =SUM(T$2:T21) | W21: 20 | X21: =SUM(Y$2:Y21) | Y21: =IF($B$5=$Y$1,INDEX(Books!$C$1:$C$701,2+($B$13-1)*20+W21-1),0) | Z21: =IF($B$5=$Y$1,INDEX(Books!$D$1:$D$701,2+($B$13-1)*20+W21-1),0) | AA21: =IF($B$5=$Y$1,INDEX(Books!$E$1:$E$701,2+($B$13-1)*20+W21-1),0) | AB21: =IF($B$5=$Y$1,INDEX(Books!$F$1:$F$701,2+($B$13-1)*20+W21-1),0) | AC21: =SUM(AB$2:AB21)
A23: Tender evaluation (Objective 1: price it off the order book)
A25: Commission per share (brief: $0.02) | B25: 0.02 | G25: Level | H25: Price | I25: Size x refill | J25: Before | K25: Taken | L25: Value
A26: Book refill factor (bot: 2.0) | B26: 2 | G26: 1 | H26: =IF($B$7="",0,IF($B$7>0,CHOOSE($B$6,J2,R2,Z2),CHOOSE($B$6,K2,S2,AA2))) | I26: =IF($B$7="",0,IF($B$7>0,CHOOSE($B$6,I2,Q2,Y2),CHOOSE($B$6,L2,T2,AB2))*$B$26) | J26: =0 | K26: =IF($B$32="",0,MIN(I26,MAX(0,$B$32-J26))) | L26: =H26*K26
A27: Min profit per share (bot: 0.01) | B27: 0.01 | G27: 2 | H27: =IF($B$7="",0,IF($B$7>0,CHOOSE($B$6,J3,R3,Z3),CHOOSE($B$6,K3,S3,AA3))) | I27: =IF($B$7="",0,IF($B$7>0,CHOOSE($B$6,I3,Q3,Y3),CHOOSE($B$6,L3,T3,AB3))*$B$26) | J27: =J26+I26 | K27: =IF($B$32="",0,MIN(I27,MAX(0,$B$32-J27))) | L27: =H27*K27
A28: Exit cost if held to the bell (per share) | B28: 0.01 | G28: 3 | H28: =IF($B$7="",0,IF($B$7>0,CHOOSE($B$6,J4,R4,Z4),CHOOSE($B$6,K4,S4,AA4))) | I28: =IF($B$7="",0,IF($B$7>0,CHOOSE($B$6,I4,Q4,Y4),CHOOSE($B$6,L4,T4,AB4))*$B$26) | J28: =J27+I27 | K28: =IF($B$32="",0,MIN(I28,MAX(0,$B$32-J28))) | L28: =H28*K28
A29: Auction margin (bot: 0.05) | B29: 0.05 | G29: 4 | H29: =IF($B$7="",0,IF($B$7>0,CHOOSE($B$6,J5,R5,Z5),CHOOSE($B$6,K5,S5,AA5))) | I29: =IF($B$7="",0,IF($B$7>0,CHOOSE($B$6,I5,Q5,Y5),CHOOSE($B$6,L5,T5,AB5))*$B$26) | J29: =J28+I28 | K29: =IF($B$32="",0,MIN(I29,MAX(0,$B$32-J29))) | L29: =H29*K29
G30: 5 | H30: =IF($B$7="",0,IF($B$7>0,CHOOSE($B$6,J6,R6,Z6),CHOOSE($B$6,K6,S6,AA6))) | I30: =IF($B$7="",0,IF($B$7>0,CHOOSE($B$6,I6,Q6,Y6),CHOOSE($B$6,L6,T6,AB6))*$B$26) | J30: =J29+I29 | K30: =IF($B$32="",0,MIN(I30,MAX(0,$B$32-J30))) | L30: =H30*K30
A31: Unwind side | B31: =IF(B7="","",IF(B7>0,"SELL into the bids",IF(B7<0,"BUY from the asks",""))) | G31: 6 | H31: =IF($B$7="",0,IF($B$7>0,CHOOSE($B$6,J7,R7,Z7),CHOOSE($B$6,K7,S7,AA7))) | I31: =IF($B$7="",0,IF($B$7>0,CHOOSE($B$6,I7,Q7,Y7),CHOOSE($B$6,L7,T7,AB7))*$B$26) | J31: =J30+I30 | K31: =IF($B$32="",0,MIN(I31,MAX(0,$B$32-J31))) | L31: =H31*K31
A32: Shares to unwind | B32: =IF(B7="","",ABS(B7)) | G32: 7 | H32: =IF($B$7="",0,IF($B$7>0,CHOOSE($B$6,J8,R8,Z8),CHOOSE($B$6,K8,S8,AA8))) | I32: =IF($B$7="",0,IF($B$7>0,CHOOSE($B$6,I8,Q8,Y8),CHOOSE($B$6,L8,T8,AB8))*$B$26) | J32: =J31+I31 | K32: =IF($B$32="",0,MIN(I32,MAX(0,$B$32-J32))) | L32: =H32*K32
A33: Mid now | B33: =IFERROR((CHOOSE(B6,J2,R2,Z2)+CHOOSE(B6,K2,S2,AA2))/2,"") | G33: 8 | H33: =IF($B$7="",0,IF($B$7>0,CHOOSE($B$6,J9,R9,Z9),CHOOSE($B$6,K9,S9,AA9))) | I33: =IF($B$7="",0,IF($B$7>0,CHOOSE($B$6,I9,Q9,Y9),CHOOSE($B$6,L9,T9,AB9))*$B$26) | J33: =J32+I32 | K33: =IF($B$32="",0,MIN(I33,MAX(0,$B$32-J33))) | L33: =H33*K33
A34: Exit VWAP walking the book (x refill) | B34: =IF(OR(B32="",K46=0),"",(L46+(B32-K46)*(INDEX(H26:H45,COUNTIF(K26:K45,">0"))-SIGN(B7)*0.05))/B32) | G34: 9 | H34: =IF($B$7="",0,IF($B$7>0,CHOOSE($B$6,J10,R10,Z10),CHOOSE($B$6,K10,S10,AA10))) | I34: =IF($B$7="",0,IF($B$7>0,CHOOSE($B$6,I10,Q10,Y10),CHOOSE($B$6,L10,T10,AB10))*$B$26) | J34: =J33+I33 | K34: =IF($B$32="",0,MIN(I34,MAX(0,$B$32-J34))) | L34: =H34*K34
A35: Shares beyond the visible book | B35: =IF(B32="","",B32-K46) | G35: 10 | H35: =IF($B$7="",0,IF($B$7>0,CHOOSE($B$6,J11,R11,Z11),CHOOSE($B$6,K11,S11,AA11))) | I35: =IF($B$7="",0,IF($B$7>0,CHOOSE($B$6,I11,Q11,Y11),CHOOSE($B$6,L11,T11,AB11))*$B$26) | J35: =J34+I34 | K35: =IF($B$32="",0,MIN(I35,MAX(0,$B$32-J35))) | L35: =H35*K35
A36: Profit/share walking the book, after commission | B36: =IF(OR(B8="",B8=0,B34=""),"",SIGN(B7)*(B34-B8)-B25) | G36: 11 | H36: =IF($B$7="",0,IF($B$7>0,CHOOSE($B$6,J12,R12,Z12),CHOOSE($B$6,K12,S12,AA12))) | I36: =IF($B$7="",0,IF($B$7>0,CHOOSE($B$6,I12,Q12,Y12),CHOOSE($B$6,L12,T12,AB12))*$B$26) | J36: =J35+I35 | K36: =IF($B$32="",0,MIN(I36,MAX(0,$B$32-J36))) | L36: =H36*K36
A37: Total profit walking the book | B37: =IF(B36="","",B36*B32) | G37: 12 | H37: =IF($B$7="",0,IF($B$7>0,CHOOSE($B$6,J13,R13,Z13),CHOOSE($B$6,K13,S13,AA13))) | I37: =IF($B$7="",0,IF($B$7>0,CHOOSE($B$6,I13,Q13,Y13),CHOOSE($B$6,L13,T13,AB13))*$B$26) | J37: =J36+I36 | K37: =IF($B$32="",0,MIN(I37,MAX(0,$B$32-J37))) | L37: =H37*K37
A38: Edge vs the mid per share | B38: =IF(OR(B8="",B8=0,B33=""),"",SIGN(B7)*(B33-B8)) | G38: 13 | H38: =IF($B$7="",0,IF($B$7>0,CHOOSE($B$6,J14,R14,Z14),CHOOSE($B$6,K14,S14,AA14))) | I38: =IF($B$7="",0,IF($B$7>0,CHOOSE($B$6,I14,Q14,Y14),CHOOSE($B$6,L14,T14,AB14))*$B$26) | J38: =J37+I37 | K38: =IF($B$32="",0,MIN(I38,MAX(0,$B$32-J38))) | L38: =H38*K38
A39: Profit/share if held to the bell | B39: =IF(B38="","",B38-B28) | G39: 14 | H39: =IF($B$7="",0,IF($B$7>0,CHOOSE($B$6,J15,R15,Z15),CHOOSE($B$6,K15,S15,AA15))) | I39: =IF($B$7="",0,IF($B$7>0,CHOOSE($B$6,I15,Q15,Y15),CHOOSE($B$6,L15,T15,AB15))*$B$26) | J39: =J38+I38 | K39: =IF($B$32="",0,MIN(I39,MAX(0,$B$32-J39))) | L39: =H39*K39
A40: Decision (walk the book vs min profit) | B40: =IF(B7="","",IF(OR(B8="",B8=0),"AUCTION: bid "&TEXT(B41,"0.00"),IF(B36>=B27,"ACCEPT","DECLINE"))) | G40: 15 | H40: =IF($B$7="",0,IF($B$7>0,CHOOSE($B$6,J16,R16,Z16),CHOOSE($B$6,K16,S16,AA16))) | I40: =IF($B$7="",0,IF($B$7>0,CHOOSE($B$6,I16,Q16,Y16),CHOOSE($B$6,L16,T16,AB16))*$B$26) | J40: =J39+I39 | K40: =IF($B$32="",0,MIN(I40,MAX(0,$B$32-J40))) | L40: =H40*K40
A41: Auction: most aggressive bid that keeps the margin | B41: =IF(B34="","",ROUND(B34-SIGN(B7)*(B25+B29),2)) | G41: 16 | H41: =IF($B$7="",0,IF($B$7>0,CHOOSE($B$6,J17,R17,Z17),CHOOSE($B$6,K17,S17,AA17))) | I41: =IF($B$7="",0,IF($B$7>0,CHOOSE($B$6,I17,Q17,Y17),CHOOSE($B$6,L17,T17,AB17))*$B$26) | J41: =J40+I40 | K41: =IF($B$32="",0,MIN(I41,MAX(0,$B$32-J41))) | L41: =H41*K41
A42: Limits: brief 250,000 gross / 100,000 net shares (enforced) | G42: 17 | H42: =IF($B$7="",0,IF($B$7>0,CHOOSE($B$6,J18,R18,Z18),CHOOSE($B$6,K18,S18,AA18))) | I42: =IF($B$7="",0,IF($B$7>0,CHOOSE($B$6,I18,Q18,Y18),CHOOSE($B$6,L18,T18,AB18))*$B$26) | J42: =J41+I41 | K42: =IF($B$32="",0,MIN(I42,MAX(0,$B$32-J42))) | L42: =H42*K42
...

Sheet Live (RTD)
A1: Current tick | B1: =IFERROR(B2-RTD("rit2.rtd",,"TIMEREMAINING"),"") | G1: Security | H1: 1 | I1: CRZY | P1: 2 | Q1: TAME | X1: 3 | Y1: CROC
A2: Total tick | B2: 420 | G2: 1 | H2: =SUM(I$2:I2) | I2: =IFERROR(--RTD("rit2.rtd",,$I$1,"AGBSZ",G2),0) | J2: =IFERROR(--RTD("rit2.rtd",,$I$1,"AGBID",G2),0) | K2: =IFERROR(--RTD("rit2.rtd",,$I$1,"AGASK",G2),0) | L2: =IFERROR(--RTD("rit2.rtd",,$I$1,"AGASZ",G2),0) | M2: =SUM(L$2:L2) | O2: 1 | P2: =SUM(Q$2:Q2) | Q2: =IFERROR(--RTD("rit2.rtd",,$Q$1,"AGBSZ",O2),0) | R2: =IFERROR(--RTD("rit2.rtd",,$Q$1,"AGBID",O2),0) | S2: =IFERROR(--RTD("rit2.rtd",,$Q$1,"AGASK",O2),0) | T2: =IFERROR(--RTD("rit2.rtd",,$Q$1,"AGASZ",O2),0) | U2: =SUM(T$2:T2) | W2: 1 | X2: =SUM(Y$2:Y2) | Y2: =IFERROR(--RTD("rit2.rtd",,$Y$1,"AGBSZ",W2),0) | Z2: =IFERROR(--RTD("rit2.rtd",,$Y$1,"AGBID",W2),0) | AA2: =IFERROR(--RTD("rit2.rtd",,$Y$1,"AGASK",W2),0) | AB2: =IFERROR(--RTD("rit2.rtd",,$Y$1,"AGASZ",W2),0) | AC2: =SUM(AB$2:AB2)
A3: Tenders | G3: 2 | H3: =SUM(I$2:I3) | I3: =IFERROR(--RTD("rit2.rtd",,$I$1,"AGBSZ",G3),0) | J3: =IFERROR(--RTD("rit2.rtd",,$I$1,"AGBID",G3),0) | K3: =IFERROR(--RTD("rit2.rtd",,$I$1,"AGASK",G3),0) | L3: =IFERROR(--RTD("rit2.rtd",,$I$1,"AGASZ",G3),0) | M3: =SUM(L$2:L3) | O3: 2 | P3: =SUM(Q$2:Q3) | Q3: =IFERROR(--RTD("rit2.rtd",,$Q$1,"AGBSZ",O3),0) | R3: =IFERROR(--RTD("rit2.rtd",,$Q$1,"AGBID",O3),0) | S3: =IFERROR(--RTD("rit2.rtd",,$Q$1,"AGASK",O3),0) | T3: =IFERROR(--RTD("rit2.rtd",,$Q$1,"AGASZ",O3),0) | U3: =SUM(T$2:T3) | W3: 2 | X3: =SUM(Y$2:Y3) | Y3: =IFERROR(--RTD("rit2.rtd",,$Y$1,"AGBSZ",W3),0) | Z3: =IFERROR(--RTD("rit2.rtd",,$Y$1,"AGBID",W3),0) | AA3: =IFERROR(--RTD("rit2.rtd",,$Y$1,"AGASK",W3),0) | AB3: =IFERROR(--RTD("rit2.rtd",,$Y$1,"AGASZ",W3),0) | AC3: =SUM(AB$2:AB3)
A4: Tender ID | B4: =IFERROR(VALUE(LEFT(E4,FIND(",",E4)-1)),"") | D4: Full text | E4: =IFERROR(RTD("rit2.rtd",,"TENDERINFO",1),"") | G4: 3 | H4: =SUM(I$2:I4) | I4: =IFERROR(--RTD("rit2.rtd",,$I$1,"AGBSZ",G4),0) | J4: =IFERROR(--RTD("rit2.rtd",,$I$1,"AGBID",G4),0) | K4: =IFERROR(--RTD("rit2.rtd",,$I$1,"AGASK",G4),0) | L4: =IFERROR(--RTD("rit2.rtd",,$I$1,"AGASZ",G4),0) | M4: =SUM(L$2:L4) | O4: 3 | P4: =SUM(Q$2:Q4) | Q4: =IFERROR(--RTD("rit2.rtd",,$Q$1,"AGBSZ",O4),0) | R4: =IFERROR(--RTD("rit2.rtd",,$Q$1,"AGBID",O4),0) | S4: =IFERROR(--RTD("rit2.rtd",,$Q$1,"AGASK",O4),0) | T4: =IFERROR(--RTD("rit2.rtd",,$Q$1,"AGASZ",O4),0) | U4: =SUM(T$2:T4) | W4: 3 | X4: =SUM(Y$2:Y4) | Y4: =IFERROR(--RTD("rit2.rtd",,$Y$1,"AGBSZ",W4),0) | Z4: =IFERROR(--RTD("rit2.rtd",,$Y$1,"AGBID",W4),0) | AA4: =IFERROR(--RTD("rit2.rtd",,$Y$1,"AGASK",W4),0) | AB4: =IFERROR(--RTD("rit2.rtd",,$Y$1,"AGASZ",W4),0) | AC4: =SUM(AB$2:AB4)
A5: Security | B5: =IFERROR(LEFT(E5,FIND(",",E5)-1),"") | D5: remain 1 | E5: =IFERROR(MID(E4,FIND(",",E4)+1,999),"") | G5: 4 | H5: =SUM(I$2:I5) | I5: =IFERROR(--RTD("rit2.rtd",,$I$1,"AGBSZ",G5),0) | J5: =IFERROR(--RTD("rit2.rtd",,$I$1,"AGBID",G5),0) | K5: =IFERROR(--RTD("rit2.rtd",,$I$1,"AGASK",G5),0) | L5: =IFERROR(--RTD("rit2.rtd",,$I$1,"AGASZ",G5),0) | M5: =SUM(L$2:L5) | O5: 4 | P5: =SUM(Q$2:Q5) | Q5: =IFERROR(--RTD("rit2.rtd",,$Q$1,"AGBSZ",O5),0) | R5: =IFERROR(--RTD("rit2.rtd",,$Q$1,"AGBID",O5),0) | S5: =IFERROR(--RTD("rit2.rtd",,$Q$1,"AGASK",O5),0) | T5: =IFERROR(--RTD("rit2.rtd",,$Q$1,"AGASZ",O5),0) | U5: =SUM(T$2:T5) | W5: 4 | X5: =SUM(Y$2:Y5) | Y5: =IFERROR(--RTD("rit2.rtd",,$Y$1,"AGBSZ",W5),0) | Z5: =IFERROR(--RTD("rit2.rtd",,$Y$1,"AGBID",W5),0) | AA5: =IFERROR(--RTD("rit2.rtd",,$Y$1,"AGASK",W5),0) | AB5: =IFERROR(--RTD("rit2.rtd",,$Y$1,"AGASZ",W5),0) | AC5: =SUM(AB$2:AB5)
A6: Sec Number | B6: =IF(B5="","",IF(B5="CRZY",1,IF(B5="TAME",2,3))) | D6: remain 2 | E6: =IFERROR(MID(E5,FIND(",",E5)+1,999),"") | G6: 5 | H6: =SUM(I$2:I6) | I6: =IFERROR(--RTD("rit2.rtd",,$I$1,"AGBSZ",G6),0) | J6: =IFERROR(--RTD("rit2.rtd",,$I$1,"AGBID",G6),0) | K6: =IFERROR(--RTD("rit2.rtd",,$I$1,"AGASK",G6),0) | L6: =IFERROR(--RTD("rit2.rtd",,$I$1,"AGASZ",G6),0) | M6: =SUM(L$2:L6) | O6: 5 | P6: =SUM(Q$2:Q6) | Q6: =IFERROR(--RTD("rit2.rtd",,$Q$1,"AGBSZ",O6),0) | R6: =IFERROR(--RTD("rit2.rtd",,$Q$1,"AGBID",O6),0) | S6: =IFERROR(--RTD("rit2.rtd",,$Q$1,"AGASK",O6),0) | T6: =IFERROR(--RTD("rit2.rtd",,$Q$1,"AGASZ",O6),0) | U6: =SUM(T$2:T6) | W6: 5 | X6: =SUM(Y$2:Y6) | Y6: =IFERROR(--RTD("rit2.rtd",,$Y$1,"AGBSZ",W6),0) | Z6: =IFERROR(--RTD("rit2.rtd",,$Y$1,"AGBID",W6),0) | AA6: =IFERROR(--RTD("rit2.rtd",,$Y$1,"AGASK",W6),0) | AB6: =IFERROR(--RTD("rit2.rtd",,$Y$1,"AGASZ",W6),0) | AC6: =SUM(AB$2:AB6)
A7: Volume | B7: =IFERROR(VALUE(LEFT(E6,FIND(",",E6)-1)),"") | C7: =IFERROR(IF(B7>0,"BUY",IF(B7<0,"SELL","")),"") | D7: remain 3 | E7: =IFERROR(MID(E6,FIND(",",E6)+1,999),"") | G7: 6 | H7: =SUM(I$2:I7) | I7: =IFERROR(--RTD("rit2.rtd",,$I$1,"AGBSZ",G7),0) | J7: =IFERROR(--RTD("rit2.rtd",,$I$1,"AGBID",G7),0) | K7: =IFERROR(--RTD("rit2.rtd",,$I$1,"AGASK",G7),0) | L7: =IFERROR(--RTD("rit2.rtd",,$I$1,"AGASZ",G7),0) | M7: =SUM(L$2:L7) | O7: 6 | P7: =SUM(Q$2:Q7) | Q7: =IFERROR(--RTD("rit2.rtd",,$Q$1,"AGBSZ",O7),0) | R7: =IFERROR(--RTD("rit2.rtd",,$Q$1,"AGBID",O7),0) | S7: =IFERROR(--RTD("rit2.rtd",,$Q$1,"AGASK",O7),0) | T7: =IFERROR(--RTD("rit2.rtd",,$Q$1,"AGASZ",O7),0) | U7: =SUM(T$2:T7) | W7: 6 | X7: =SUM(Y$2:Y7) | Y7: =IFERROR(--RTD("rit2.rtd",,$Y$1,"AGBSZ",W7),0) | Z7: =IFERROR(--RTD("rit2.rtd",,$Y$1,"AGBID",W7),0) | AA7: =IFERROR(--RTD("rit2.rtd",,$Y$1,"AGASK",W7),0) | AB7: =IFERROR(--RTD("rit2.rtd",,$Y$1,"AGASZ",W7),0) | AC7: =SUM(AB$2:AB7)
A8: Price | B8: =IFERROR(VALUE(LEFT(E7,FIND(",",E7)-1)),"") | D8: remain 4 | E8: =IFERROR(MID(E7,FIND(",",E7)+1,999),"") | G8: 7 | H8: =SUM(I$2:I8) | I8: =IFERROR(--RTD("rit2.rtd",,$I$1,"AGBSZ",G8),0) | J8: =IFERROR(--RTD("rit2.rtd",,$I$1,"AGBID",G8),0) | K8: =IFERROR(--RTD("rit2.rtd",,$I$1,"AGASK",G8),0) | L8: =IFERROR(--RTD("rit2.rtd",,$I$1,"AGASZ",G8),0) | M8: =SUM(L$2:L8) | O8: 7 | P8: =SUM(Q$2:Q8) | Q8: =IFERROR(--RTD("rit2.rtd",,$Q$1,"AGBSZ",O8),0) | R8: =IFERROR(--RTD("rit2.rtd",,$Q$1,"AGBID",O8),0) | S8: =IFERROR(--RTD("rit2.rtd",,$Q$1,"AGASK",O8),0) | T8: =IFERROR(--RTD("rit2.rtd",,$Q$1,"AGASZ",O8),0) | U8: =SUM(T$2:T8) | W8: 7 | X8: =SUM(Y$2:Y8) | Y8: =IFERROR(--RTD("rit2.rtd",,$Y$1,"AGBSZ",W8),0) | Z8: =IFERROR(--RTD("rit2.rtd",,$Y$1,"AGBID",W8),0) | AA8: =IFERROR(--RTD("rit2.rtd",,$Y$1,"AGASK",W8),0) | AB8: =IFERROR(--RTD("rit2.rtd",,$Y$1,"AGASZ",W8),0) | AC8: =SUM(AB$2:AB8)
A9: Tick received | B9: =IFERROR(VALUE(LEFT(E8,FIND(",",E8)-1)),"") | D9: remain 5 | E9: =IFERROR(MID(E8,FIND(",",E8)+1,999),"") | G9: 8 | H9: =SUM(I$2:I9) | I9: =IFERROR(--RTD("rit2.rtd",,$I$1,"AGBSZ",G9),0) | J9: =IFERROR(--RTD("rit2.rtd",,$I$1,"AGBID",G9),0) | K9: =IFERROR(--RTD("rit2.rtd",,$I$1,"AGASK",G9),0) | L9: =IFERROR(--RTD("rit2.rtd",,$I$1,"AGASZ",G9),0) | M9: =SUM(L$2:L9) | O9: 8 | P9: =SUM(Q$2:Q9) | Q9: =IFERROR(--RTD("rit2.rtd",,$Q$1,"AGBSZ",O9),0) | R9: =IFERROR(--RTD("rit2.rtd",,$Q$1,"AGBID",O9),0) | S9: =IFERROR(--RTD("rit2.rtd",,$Q$1,"AGASK",O9),0) | T9: =IFERROR(--RTD("rit2.rtd",,$Q$1,"AGASZ",O9),0) | U9: =SUM(T$2:T9) | W9: 8 | X9: =SUM(Y$2:Y9) | Y9: =IFERROR(--RTD("rit2.rtd",,$Y$1,"AGBSZ",W9),0) | Z9: =IFERROR(--RTD("rit2.rtd",,$Y$1,"AGBID",W9),0) | AA9: =IFERROR(--RTD("rit2.rtd",,$Y$1,"AGASK",W9),0) | AB9: =IFERROR(--RTD("rit2.rtd",,$Y$1,"AGASZ",W9),0) | AC9: =SUM(AB$2:AB9)
A10: Tick expired | B10: =IFERROR(VALUE(E9),"") | G10: 9 | H10: =SUM(I$2:I10) | I10: =IFERROR(--RTD("rit2.rtd",,$I$1,"AGBSZ",G10),0) | J10: =IFERROR(--RTD("rit2.rtd",,$I$1,"AGBID",G10),0) | K10: =IFERROR(--RTD("rit2.rtd",,$I$1,"AGASK",G10),0) | L10: =IFERROR(--RTD("rit2.rtd",,$I$1,"AGASZ",G10),0) | M10: =SUM(L$2:L10) | O10: 9 | P10: =SUM(Q$2:Q10) | Q10: =IFERROR(--RTD("rit2.rtd",,$Q$1,"AGBSZ",O10),0) | R10: =IFERROR(--RTD("rit2.rtd",,$Q$1,"AGBID",O10),0) | S10: =IFERROR(--RTD("rit2.rtd",,$Q$1,"AGASK",O10),0) | T10: =IFERROR(--RTD("rit2.rtd",,$Q$1,"AGASZ",O10),0) | U10: =SUM(T$2:T10) | W10: 9 | X10: =SUM(Y$2:Y10) | Y10: =IFERROR(--RTD("rit2.rtd",,$Y$1,"AGBSZ",W10),0) | Z10: =IFERROR(--RTD("rit2.rtd",,$Y$1,"AGBID",W10),0) | AA10: =IFERROR(--RTD("rit2.rtd",,$Y$1,"AGASK",W10),0) | AB10: =IFERROR(--RTD("rit2.rtd",,$Y$1,"AGASZ",W10),0) | AC10: =SUM(AB$2:AB10)
A11: Ticks left to decide | B11: =IF(OR(B10="",B1=""),"",B10-B1) | G11: 10 | H11: =SUM(I$2:I11) | I11: =IFERROR(--RTD("rit2.rtd",,$I$1,"AGBSZ",G11),0) | J11: =IFERROR(--RTD("rit2.rtd",,$I$1,"AGBID",G11),0) | K11: =IFERROR(--RTD("rit2.rtd",,$I$1,"AGASK",G11),0) | L11: =IFERROR(--RTD("rit2.rtd",,$I$1,"AGASZ",G11),0) | M11: =SUM(L$2:L11) | O11: 10 | P11: =SUM(Q$2:Q11) | Q11: =IFERROR(--RTD("rit2.rtd",,$Q$1,"AGBSZ",O11),0) | R11: =IFERROR(--RTD("rit2.rtd",,$Q$1,"AGBID",O11),0) | S11: =IFERROR(--RTD("rit2.rtd",,$Q$1,"AGASK",O11),0) | T11: =IFERROR(--RTD("rit2.rtd",,$Q$1,"AGASZ",O11),0) | U11: =SUM(T$2:T11) | W11: 10 | X11: =SUM(Y$2:Y11) | Y11: =IFERROR(--RTD("rit2.rtd",,$Y$1,"AGBSZ",W11),0) | Z11: =IFERROR(--RTD("rit2.rtd",,$Y$1,"AGBID",W11),0) | AA11: =IFERROR(--RTD("rit2.rtd",,$Y$1,"AGASK",W11),0) | AB11: =IFERROR(--RTD("rit2.rtd",,$Y$1,"AGASZ",W11),0) | AC11: =SUM(AB$2:AB11)
G12: 11 | H12: =SUM(I$2:I12) | I12: =IFERROR(--RTD("rit2.rtd",,$I$1,"AGBSZ",G12),0) | J12: =IFERROR(--RTD("rit2.rtd",,$I$1,"AGBID",G12),0) | K12: =IFERROR(--RTD("rit2.rtd",,$I$1,"AGASK",G12),0) | L12: =IFERROR(--RTD("rit2.rtd",,$I$1,"AGASZ",G12),0) | M12: =SUM(L$2:L12) | O12: 11 | P12: =SUM(Q$2:Q12) | Q12: =IFERROR(--RTD("rit2.rtd",,$Q$1,"AGBSZ",O12),0) | R12: =IFERROR(--RTD("rit2.rtd",,$Q$1,"AGBID",O12),0) | S12: =IFERROR(--RTD("rit2.rtd",,$Q$1,"AGASK",O12),0) | T12: =IFERROR(--RTD("rit2.rtd",,$Q$1,"AGASZ",O12),0) | U12: =SUM(T$2:T12) | W12: 11 | X12: =SUM(Y$2:Y12) | Y12: =IFERROR(--RTD("rit2.rtd",,$Y$1,"AGBSZ",W12),0) | Z12: =IFERROR(--RTD("rit2.rtd",,$Y$1,"AGBID",W12),0) | AA12: =IFERROR(--RTD("rit2.rtd",,$Y$1,"AGASK",W12),0) | AB12: =IFERROR(--RTD("rit2.rtd",,$Y$1,"AGASZ",W12),0) | AC12: =SUM(AB$2:AB12)
